2018-01-25 00:41:07,842 - util.py[DEBUG]: Cloud-init v. 17.1 running 'init-local' at Thu, 25 Jan 2018 00:41:07 +0000. Up 6.09 seconds.
2018-01-25 00:41:07,842 - main.py[DEBUG]: No kernel command line url found.
2018-01-25 00:41:07,842 - main.py[DEBUG]: Closing stdin.
2018-01-25 00:41:07,846 - util.py[DEBUG]: Writing to /var/log/cloud-init.log - ab: [644] 0 bytes
2018-01-25 00:41:07,846 - util.py[DEBUG]: Changing the ownership of /var/log/cloud-init.log to 104:4
2018-01-25 00:41:07,847 - util.py[DEBUG]: Attempting to remove /var/lib/cloud/instance/boot-finished
2018-01-25 00:41:07,847 - util.py[DEBUG]: Attempting to remove /var/lib/cloud/data/no-net
2018-01-25 00:41:07,847 - handlers.py[DEBUG]: start: init-local/check-cache: attempting to read from cache [check]
2018-01-25 00:41:07,847 - util.py[DEBUG]: Reading from /var/lib/cloud/instance/obj.pkl (quiet=False)
2018-01-25 00:41:07,847 - stages.py[DEBUG]: no cache found
2018-01-25 00:41:07,847 - handlers.py[DEBUG]: finish: init-local/check-cache: SUCCESS: no cache found
2018-01-25 00:41:07,847 - util.py[DEBUG]: Attempting to remove /var/lib/cloud/instance
2018-01-25 00:41:07,850 - stages.py[DEBUG]: Using distro class <class 'cloudinit.distros.ubuntu.Distro'>
2018-01-25 00:41:07,851 - __init__.py[DEBUG]: Looking for for data source in: ['ConfigDrive', 'DigitalOcean', 'NoCloud', 'None'], via packages ['', 'cloudinit.sources'] that matches dependencies ['FILESYSTEM']
2018-01-25 00:41:07,856 - __init__.py[DEBUG]: Searching for local data source in: ['DataSourceConfigDrive', 'DataSourceDigitalOcean', 'DataSourceNoCloud']
2018-01-25 00:41:07,857 - handlers.py[DEBUG]: start: init-local/search-ConfigDrive: searching for local data from DataSourceConfigDrive
2018-01-25 00:41:07,857 - __init__.py[DEBUG]: Seeing if we can get any data from <class 'cloudinit.sources.DataSourceConfigDrive.DataSourceConfigDrive'>
2018-01-25 00:41:07,857 - util.py[DEBUG]: Running command ['blkid', '-odevice', '/dev/sr0'] with allowed return codes [0, 2] (shell=False, capture=True)
2018-01-25 00:41:07,859 - util.py[DEBUG]: Running command ['blkid', '-odevice', '/dev/sr1'] with allowed return codes [0, 2] (shell=False, capture=True)
2018-01-25 00:41:07,861 - util.py[DEBUG]: Running command ['blkid', '-odevice', '/dev/cd0'] with allowed return codes [0, 2] (shell=False, capture=True)
2018-01-25 00:41:07,863 - util.py[DEBUG]: Running command ['blkid', '-odevice', '/dev/cd1'] with allowed return codes [0, 2] (shell=False, capture=True)
2018-01-25 00:41:07,865 - util.py[DEBUG]: Running command ['blkid', '-tTYPE=vfat', '-odevice'] with allowed return codes [0, 2] (shell=False, capture=True)
2018-01-25 00:41:07,873 - util.py[DEBUG]: Running command ['blkid', '-tTYPE=iso9660', '-odevice'] with allowed return codes [0, 2] (shell=False, capture=True)
2018-01-25 00:41:07,877 - util.py[DEBUG]: Running command ['blkid', '-tLABEL=config-2', '-odevice'] with allowed return codes [0, 2] (shell=False, capture=True)
2018-01-25 00:41:07,881 - handlers.py[DEBUG]: finish: init-local/search-ConfigDrive: SUCCESS: no local data found from DataSourceConfigDrive
2018-01-25 00:41:07,882 - handlers.py[DEBUG]: start: init-local/search-DigitalOcean: searching for local data from DataSourceDigitalOcean
2018-01-25 00:41:07,882 - __init__.py[DEBUG]: Seeing if we can get any data from <class 'cloudinit.sources.DataSourceDigitalOcean.DataSourceDigitalOcean'>
2018-01-25 00:41:07,882 - util.py[DEBUG]: Running command ['systemd-detect-virt', '--quiet', '--container'] with allowed return codes [0] (shell=False, capture=True)
2018-01-25 00:41:07,884 - util.py[DEBUG]: Running command ['running-in-container'] with allowed return codes [0] (shell=False, capture=True)
2018-01-25 00:41:07,887 - util.py[DEBUG]: Running command ['lxc-is-container'] with allowed return codes [0] (shell=False, capture=True)
2018-01-25 00:41:07,889 - util.py[DEBUG]: Reading from /proc/1/environ (quiet=False)
2018-01-25 00:41:07,889 - util.py[DEBUG]: Read 153 bytes from /proc/1/environ
2018-01-25 00:41:07,889 - util.py[DEBUG]: Reading from /proc/self/status (quiet=False)
2018-01-25 00:41:07,889 - util.py[DEBUG]: Read 891 bytes from /proc/self/status
2018-01-25 00:41:07,889 - util.py[DEBUG]: querying dmi data /sys/class/dmi/id/sys_vendor
2018-01-25 00:41:07,890 - util.py[DEBUG]: Reading from /sys/class/dmi/id/sys_vendor (quiet=False)
2018-01-25 00:41:07,890 - util.py[DEBUG]: Read 13 bytes from /sys/class/dmi/id/sys_vendor
2018-01-25 00:41:07,890 - util.py[DEBUG]: dmi data /sys/class/dmi/id/sys_vendor returned DigitalOcean
2018-01-25 00:41:07,890 - util.py[DEBUG]: Running command ['systemd-detect-virt', '--quiet', '--container'] with allowed return codes [0] (shell=False, capture=True)
2018-01-25 00:41:07,892 - util.py[DEBUG]: Running command ['running-in-container'] with allowed return codes [0] (shell=False, capture=True)
2018-01-25 00:41:07,893 - util.py[DEBUG]: Running command ['lxc-is-container'] with allowed return codes [0] (shell=False, capture=True)
2018-01-25 00:41:07,895 - util.py[DEBUG]: Reading from /proc/1/environ (quiet=False)
2018-01-25 00:41:07,895 - util.py[DEBUG]: Read 153 bytes from /proc/1/environ
2018-01-25 00:41:07,895 - util.py[DEBUG]: Reading from /proc/self/status (quiet=False)
2018-01-25 00:41:07,895 - util.py[DEBUG]: Read 891 bytes from /proc/self/status
2018-01-25 00:41:07,895 - util.py[DEBUG]: querying dmi data /sys/class/dmi/id/product_serial
2018-01-25 00:41:07,895 - util.py[DEBUG]: Reading from /sys/class/dmi/id/product_serial (quiet=False)
2018-01-25 00:41:07,896 - util.py[DEBUG]: Read 9 bytes from /sys/class/dmi/id/product_serial
2018-01-25 00:41:07,896 - util.py[DEBUG]: dmi data /sys/class/dmi/id/product_serial returned 80040526
2018-01-25 00:41:07,896 - digitalocean.py[DEBUG]: system identified via SMBIOS as DigitalOcean Droplet: 80040526
2018-01-25 00:41:07,896 - DataSourceDigitalOcean.py[INFO]: Running on digital ocean. droplet_id=80040526
2018-01-25 00:41:07,896 - util.py[DEBUG]: Reading from /sys/class/net/ens3/ifindex (quiet=False)
2018-01-25 00:41:07,896 - util.py[DEBUG]: Read 2 bytes from /sys/class/net/ens3/ifindex
2018-01-25 00:41:07,896 - digitalocean.py[DEBUG]: selected interface 'ens3' for reading metadata
2018-01-25 00:41:07,896 - util.py[DEBUG]: Running command ['ip', 'addr', 'add', '169.254.71.143/16', 'dev', 'ens3'] with allowed return codes [0] (shell=False, capture=True)
2018-01-25 00:41:07,899 - digitalocean.py[DEBUG]: assigned ip4LL address '169.254.71.143/16' to 'ens3'
2018-01-25 00:41:07,899 - util.py[DEBUG]: Running command ['ip', 'link', 'set', 'dev', 'ens3', 'up'] with allowed return codes [0] (shell=False, capture=True)
2018-01-25 00:41:07,902 - digitalocean.py[DEBUG]: brought device 'ens3' up
2018-01-25 00:41:07,902 - url_helper.py[DEBUG]: [0/31] open 'http://169.254.169.254/metadata/v1.json' with {'timeout': 2.0, 'allow_redirects': True, 'url': 'http://169.254.169.254/metadata/v1.json', 'headers': {'User-Agent': 'Cloud-Init/17.1'}, 'method': 'GET'} configuration
2018-01-25 00:41:07,918 - url_helper.py[DEBUG]: Read from http://169.254.169.254/metadata/v1.json (200, 9916b) after 1 attempts
2018-01-25 00:41:07,918 - digitalocean.py[DEBUG]: cleaning up ipv4LL address
2018-01-25 00:41:07,918 - util.py[DEBUG]: Running command ['ip', 'addr', 'flush', 'dev', 'ens3'] with allowed return codes [0] (shell=False, capture=True)
2018-01-25 00:41:07,921 - digitalocean.py[DEBUG]: removed ip4LL addresses from ens3
2018-01-25 00:41:07,922 - handlers.py[DEBUG]: finish: init-local/search-DigitalOcean: SUCCESS: found local data from DataSourceDigitalOcean
2018-01-25 00:41:07,922 - stages.py[INFO]: Loaded datasource DataSourceDigitalOcean - DataSourceDigitalOcean
2018-01-25 00:41:07,922 - util.py[DEBUG]: Reading from /etc/cloud/cloud.cfg (quiet=False)
2018-01-25 00:41:07,922 - util.py[DEBUG]: Read 3001 bytes from /etc/cloud/cloud.cfg
2018-01-25 00:41:07,922 - util.py[DEBUG]: Attempting to load yaml from string of length 3001 with allowed root types (<class 'dict'>,)
2018-01-25 00:41:07,936 - util.py[DEBUG]: Reading from /etc/cloud/cloud.cfg.d/99-digitalocean.cfg (quiet=False)
2018-01-25 00:41:07,936 - util.py[DEBUG]: Read 168 bytes from /etc/cloud/cloud.cfg.d/99-digitalocean.cfg
2018-01-25 00:41:07,936 - util.py[DEBUG]: Attempting to load yaml from string of length 168 with allowed root types (<class 'dict'>,)
2018-01-25 00:41:07,937 - util.py[DEBUG]: Reading from /etc/cloud/cloud.cfg.d/90_dpkg.cfg (quiet=False)
2018-01-25 00:41:07,937 - util.py[DEBUG]: Read 238 bytes from /etc/cloud/cloud.cfg.d/90_dpkg.cfg
2018-01-25 00:41:07,938 - util.py[DEBUG]: Attempting to load yaml from string of length 238 with allowed root types (<class 'dict'>,)
2018-01-25 00:41:07,939 - util.py[DEBUG]: Reading from /etc/cloud/cloud.cfg.d/05_logging.cfg (quiet=False)
2018-01-25 00:41:07,940 - util.py[DEBUG]: Read 2057 bytes from /etc/cloud/cloud.cfg.d/05_logging.cfg
2018-01-25 00:41:07,940 - util.py[DEBUG]: Attempting to load yaml from string of length 2057 with allowed root types (<class 'dict'>,)
2018-01-25 00:41:07,944 - util.py[DEBUG]: Reading from /run/cloud-init/cloud.cfg (quiet=False)
2018-01-25 00:41:07,944 - util.py[DEBUG]: Read 53 bytes from /run/cloud-init/cloud.cfg
2018-01-25 00:41:07,944 - util.py[DEBUG]: Attempting to load yaml from string of length 53 with allowed root types (<class 'dict'>,)
2018-01-25 00:41:07,945 - util.py[DEBUG]: Attempting to load yaml from string of length 0 with allowed root types (<class 'dict'>,)
2018-01-25 00:41:07,945 - util.py[DEBUG]: load_yaml given empty string, returning default
2018-01-25 00:41:07,946 - util.py[DEBUG]: Attempting to remove /var/lib/cloud/instance
2018-01-25 00:41:07,946 - util.py[DEBUG]: Creating symbolic link from '/var/lib/cloud/instance' => '/var/lib/cloud/instances/80040526'
2018-01-25 00:41:07,947 - util.py[DEBUG]: Reading from /var/lib/cloud/instances/80040526/datasource (quiet=False)
2018-01-25 00:41:07,947 - util.py[DEBUG]: Writing to /var/lib/cloud/instances/80040526/datasource - wb: [644] 47 bytes
2018-01-25 00:41:07,948 - util.py[DEBUG]: Writing to /var/lib/cloud/data/previous-datasource - wb: [644] 47 bytes
2018-01-25 00:41:07,948 - util.py[DEBUG]: Reading from /var/lib/cloud/data/instance-id (quiet=False)
2018-01-25 00:41:07,948 - stages.py[DEBUG]: previous iid found to be NO_PREVIOUS_INSTANCE_ID
2018-01-25 00:41:07,949 - util.py[DEBUG]: Writing to /var/lib/cloud/data/instance-id - wb: [644] 9 bytes
2018-01-25 00:41:07,949 - util.py[DEBUG]: Writing to /run/cloud-init/.instance-id - wb: [644] 9 bytes
2018-01-25 00:41:07,950 - util.py[DEBUG]: Writing to /var/lib/cloud/data/previous-instance-id - wb: [644] 24 bytes
2018-01-25 00:41:07,950 - util.py[DEBUG]: Writing to /var/lib/cloud/instance/obj.pkl - wb: [400] 15088 bytes
2018-01-25 00:41:07,951 - main.py[DEBUG]: [local] init will now be targeting instance id: 80040526. new=True
2018-01-25 00:41:07,951 - util.py[DEBUG]: Reading from /etc/cloud/cloud.cfg (quiet=False)
2018-01-25 00:41:07,951 - util.py[DEBUG]: Read 3001 bytes from /etc/cloud/cloud.cfg
2018-01-25 00:41:07,951 - util.py[DEBUG]: Attempting to load yaml from string of length 3001 with allowed root types (<class 'dict'>,)
2018-01-25 00:41:07,964 - util.py[DEBUG]: Reading from /etc/cloud/cloud.cfg.d/99-digitalocean.cfg (quiet=False)
2018-01-25 00:41:07,965 - util.py[DEBUG]: Read 168 bytes from /etc/cloud/cloud.cfg.d/99-digitalocean.cfg
2018-01-25 00:41:07,965 - util.py[DEBUG]: Attempting to load yaml from string of length 168 with allowed root types (<class 'dict'>,)
2018-01-25 00:41:07,965 - util.py[DEBUG]: Reading from /etc/cloud/cloud.cfg.d/90_dpkg.cfg (quiet=False)
2018-01-25 00:41:07,966 - util.py[DEBUG]: Read 238 bytes from /etc/cloud/cloud.cfg.d/90_dpkg.cfg
2018-01-25 00:41:07,966 - util.py[DEBUG]: Attempting to load yaml from string of length 238 with allowed root types (<class 'dict'>,)
2018-01-25 00:41:07,967 - util.py[DEBUG]: Reading from /etc/cloud/cloud.cfg.d/05_logging.cfg (quiet=False)
2018-01-25 00:41:07,967 - util.py[DEBUG]: Read 2057 bytes from /etc/cloud/cloud.cfg.d/05_logging.cfg
2018-01-25 00:41:07,967 - util.py[DEBUG]: Attempting to load yaml from string of length 2057 with allowed root types (<class 'dict'>,)
2018-01-25 00:41:07,972 - util.py[DEBUG]: Reading from /run/cloud-init/cloud.cfg (quiet=False)
2018-01-25 00:41:07,972 - util.py[DEBUG]: Read 53 bytes from /run/cloud-init/cloud.cfg
2018-01-25 00:41:07,972 - util.py[DEBUG]: Attempting to load yaml from string of length 53 with allowed root types (<class 'dict'>,)
2018-01-25 00:41:07,973 - util.py[DEBUG]: Attempting to load yaml from string of length 0 with allowed root types (<class 'dict'>,)
2018-01-25 00:41:07,973 - util.py[DEBUG]: load_yaml given empty string, returning default
2018-01-25 00:41:07,973 - DataSourceDigitalOcean.py[DEBUG]: {'public': [{'anchor_ipv4': {'netmask': '255.255.0.0', 'ip_address': '10.46.0.5', 'gateway': '10.46.0.1'}, 'type': 'public', 'mac': '0e:43:e6:58:14:52', 'ipv4': {'netmask': '255.255.240.0', 'ip_address': '159.89.146.218', 'gateway': '159.89.144.1'}}]}
2018-01-25 00:41:07,974 - util.py[DEBUG]: Reading from /sys/class/net/ens3/addr_assign_type (quiet=False)
2018-01-25 00:41:07,974 - util.py[DEBUG]: Read 2 bytes from /sys/class/net/ens3/addr_assign_type
2018-01-25 00:41:07,974 - util.py[DEBUG]: Reading from /sys/class/net/ens3/uevent (quiet=False)
2018-01-25 00:41:07,974 - util.py[DEBUG]: Read 25 bytes from /sys/class/net/ens3/uevent
2018-01-25 00:41:07,974 - util.py[DEBUG]: Reading from /sys/class/net/ens3/address (quiet=False)
2018-01-25 00:41:07,974 - util.py[DEBUG]: Read 18 bytes from /sys/class/net/ens3/address
2018-01-25 00:41:07,974 - util.py[DEBUG]: Reading from /sys/class/net/ens3/device/device (quiet=False)
2018-01-25 00:41:07,974 - util.py[DEBUG]: Read 7 bytes from /sys/class/net/ens3/device/device
2018-01-25 00:41:07,974 - util.py[DEBUG]: Reading from /sys/class/net/lo/addr_assign_type (quiet=False)
2018-01-25 00:41:07,974 - util.py[DEBUG]: Read 2 bytes from /sys/class/net/lo/addr_assign_type
2018-01-25 00:41:07,974 - util.py[DEBUG]: Reading from /sys/class/net/lo/uevent (quiet=False)
2018-01-25 00:41:07,975 - util.py[DEBUG]: Read 23 bytes from /sys/class/net/lo/uevent
2018-01-25 00:41:07,975 - util.py[DEBUG]: Reading from /sys/class/net/lo/address (quiet=False)
2018-01-25 00:41:07,975 - util.py[DEBUG]: Read 18 bytes from /sys/class/net/lo/address
2018-01-25 00:41:07,975 - util.py[DEBUG]: Reading from /sys/class/net/lo/device/device (quiet=False)
2018-01-25 00:41:07,975 - digitalocean.py[DEBUG]: nic mapping: {'0e:43:e6:58:14:52': 'ens3', '00:00:00:00:00:00': 'lo'}
2018-01-25 00:41:07,975 - digitalocean.py[DEBUG]: considering {'anchor_ipv4': {'netmask': '255.255.0.0', 'ip_address': '10.46.0.5', 'gateway': '10.46.0.1'}, 'type': 'public', 'mac': '0e:43:e6:58:14:52', 'ipv4': {'netmask': '255.255.240.0', 'ip_address': '159.89.146.218', 'gateway': '159.89.144.1'}}
2018-01-25 00:41:07,975 - digitalocean.py[DEBUG]: Found public interface '0e:43:e6:58:14:52' on 'ens3', assigned name of 'eth0'
2018-01-25 00:41:07,975 - digitalocean.py[DEBUG]: nic 'eth0' configuration: {'subnets': [{'netmask': '255.255.240.0', 'control': 'auto', 'type': 'static', 'gateway': '159.89.144.1', 'address': '159.89.146.218'}, {'netmask': '255.255.0.0', 'control': 'auto', 'type': 'static', 'address': '10.46.0.5'}], 'type': 'physical', 'mac_address': '0e:43:e6:58:14:52', 'name': 'eth0'}
2018-01-25 00:41:07,975 - digitalocean.py[DEBUG]: added dns servers: ['67.207.67.2', '67.207.67.3']
2018-01-25 00:41:07,975 - stages.py[DEBUG]: applying net config names for {'version': 1, 'config': [{'subnets': [{'netmask': '255.255.240.0', 'control': 'auto', 'type': 'static', 'gateway': '159.89.144.1', 'address': '159.89.146.218'}, {'netmask': '255.255.0.0', 'control': 'auto', 'type': 'static', 'address': '10.46.0.5'}], 'type': 'physical', 'mac_address': '0e:43:e6:58:14:52', 'name': 'eth0'}, {'type': 'nameserver', 'address': ['67.207.67.2', '67.207.67.3']}]}
2018-01-25 00:41:07,976 - stages.py[DEBUG]: Using distro class <class 'cloudinit.distros.ubuntu.Distro'>
2018-01-25 00:41:07,976 - util.py[DEBUG]: Reading from /sys/class/net/eth0/device/device (quiet=False)
2018-01-25 00:41:07,976 - util.py[DEBUG]: Reading from /sys/class/net/ens3/addr_assign_type (quiet=False)
2018-01-25 00:41:07,976 - util.py[DEBUG]: Read 2 bytes from /sys/class/net/ens3/addr_assign_type
2018-01-25 00:41:07,976 - util.py[DEBUG]: Reading from /sys/class/net/ens3/uevent (quiet=False)
2018-01-25 00:41:07,976 - util.py[DEBUG]: Read 25 bytes from /sys/class/net/ens3/uevent
2018-01-25 00:41:07,977 - util.py[DEBUG]: Reading from /sys/class/net/ens3/address (quiet=False)
2018-01-25 00:41:07,977 - util.py[DEBUG]: Read 18 bytes from /sys/class/net/ens3/address
2018-01-25 00:41:07,977 - util.py[DEBUG]: Reading from /sys/class/net/ens3/device/device (quiet=False)
2018-01-25 00:41:07,977 - util.py[DEBUG]: Read 7 bytes from /sys/class/net/ens3/device/device
2018-01-25 00:41:07,977 - util.py[DEBUG]: Reading from /sys/class/net/lo/addr_assign_type (quiet=False)
2018-01-25 00:41:07,977 - util.py[DEBUG]: Read 2 bytes from /sys/class/net/lo/addr_assign_type
2018-01-25 00:41:07,977 - util.py[DEBUG]: Reading from /sys/class/net/lo/uevent (quiet=False)
2018-01-25 00:41:07,977 - util.py[DEBUG]: Read 23 bytes from /sys/class/net/lo/uevent
2018-01-25 00:41:07,977 - util.py[DEBUG]: Reading from /sys/class/net/lo/address (quiet=False)
2018-01-25 00:41:07,977 - util.py[DEBUG]: Read 18 bytes from /sys/class/net/lo/address
2018-01-25 00:41:07,977 - util.py[DEBUG]: Reading from /sys/class/net/lo/device/device (quiet=False)
2018-01-25 00:41:07,977 - util.py[DEBUG]: Reading from /sys/class/net/ens3/operstate (quiet=False)
2018-01-25 00:41:07,978 - util.py[DEBUG]: Read 3 bytes from /sys/class/net/ens3/operstate
2018-01-25 00:41:07,978 - util.py[DEBUG]: Reading from /sys/class/net/lo/operstate (quiet=False)
2018-01-25 00:41:07,978 - util.py[DEBUG]: Read 8 bytes from /sys/class/net/lo/operstate
2018-01-25 00:41:07,978 - util.py[DEBUG]: Running command ['ip', '-6', 'addr', 'show', 'permanent', 'scope', 'global'] with allowed return codes [0] (shell=False, capture=True)
2018-01-25 00:41:07,984 - util.py[DEBUG]: Running command ['ip', '-4', 'addr', 'show'] with allowed return codes [0] (shell=False, capture=True)
2018-01-25 00:41:07,986 - __init__.py[DEBUG]: achieving renaming of [['0e:43:e6:58:14:52', 'eth0', None, None]] with ops [('down', '0e:43:e6:58:14:52', 'eth0', ('ens3',)), ('rename', '0e:43:e6:58:14:52', 'eth0', ('ens3', 'eth0')), ('up', '0e:43:e6:58:14:52', 'eth0', ('eth0',))]
2018-01-25 00:41:07,987 - util.py[DEBUG]: Running command ['ip', 'link', 'set', 'ens3', 'down'] with allowed return codes [0] (shell=False, capture=True)
2018-01-25 00:41:07,989 - util.py[DEBUG]: Running command ['ip', 'link', 'set', 'ens3', 'name', 'eth0'] with allowed return codes [0] (shell=False, capture=True)
2018-01-25 00:41:08,063 - util.py[DEBUG]: Running command ['ip', 'link', 'set', 'eth0', 'up'] with allowed return codes [0] (shell=False, capture=True)
2018-01-25 00:41:08,065 - stages.py[INFO]: Applying network configuration from ds bringup=False: {'version': 1, 'config': [{'subnets': [{'netmask': '255.255.240.0', 'control': 'auto', 'type': 'static', 'gateway': '159.89.144.1', 'address': '159.89.146.218'}, {'netmask': '255.255.0.0', 'control': 'auto', 'type': 'static', 'address': '10.46.0.5'}], 'type': 'physical', 'mac_address': '0e:43:e6:58:14:52', 'name': 'eth0'}, {'type': 'nameserver', 'address': ['67.207.67.2', '67.207.67.3']}]}
2018-01-25 00:41:08,066 - __init__.py[DEBUG]: Selected renderer 'eni' from priority list: None
2018-01-25 00:41:08,071 - util.py[DEBUG]: Writing to /etc/network/interfaces.d/50-cloud-init.cfg - wb: [644] 538 bytes
2018-01-25 00:41:08,071 - util.py[DEBUG]: Writing to /etc/udev/rules.d/70-persistent-net.rules - wb: [644] 96 bytes
2018-01-25 00:41:08,072 - main.py[DEBUG]: [local] Exiting. datasource DataSourceDigitalOcean not in local mode.
2018-01-25 00:41:08,074 - util.py[DEBUG]: Reading from /proc/uptime (quiet=False)
2018-01-25 00:41:08,074 - util.py[DEBUG]: Read 11 bytes from /proc/uptime
2018-01-25 00:41:08,074 - util.py[DEBUG]: cloud-init mode 'init' took 0.274 seconds (0.27)
2018-01-25 00:41:08,074 - handlers.py[DEBUG]: finish: init-local: SUCCESS: searching for local datasources
2018-01-25 00:41:09,118 - util.py[DEBUG]: Cloud-init v. 17.1 running 'init' at Thu, 25 Jan 2018 00:41:09 +0000. Up 7.37 seconds.
2018-01-25 00:41:09,118 - main.py[DEBUG]: No kernel command line url found.
2018-01-25 00:41:09,118 - main.py[DEBUG]: Closing stdin.
2018-01-25 00:41:09,121 - util.py[DEBUG]: Writing to /var/log/cloud-init.log - ab: [644] 0 bytes
2018-01-25 00:41:09,121 - util.py[DEBUG]: Changing the ownership of /var/log/cloud-init.log to 104:4
2018-01-25 00:41:09,122 - util.py[DEBUG]: Running command ['ifconfig', '-a'] with allowed return codes [0, 1] (shell=False, capture=True)
2018-01-25 00:41:09,126 - util.py[DEBUG]: Running command ['netstat', '-rn'] with allowed return codes [0, 1] (shell=False, capture=True)
2018-01-25 00:41:09,128 - util.py[DEBUG]: Running command ['netstat', '-A', 'inet6', '-n'] with allowed return codes [0, 1] (shell=False, capture=True)
2018-01-25 00:41:09,131 - main.py[DEBUG]: Checking to see if files that we need already exist from a previous run that would allow us to stop early.
2018-01-25 00:41:09,131 - main.py[DEBUG]: Execution continuing, no previous run detected that would allow us to stop early.
2018-01-25 00:41:09,132 - handlers.py[DEBUG]: start: init-network/check-cache: attempting to read from cache [trust]
2018-01-25 00:41:09,132 - util.py[DEBUG]: Reading from /var/lib/cloud/instance/obj.pkl (quiet=False)
2018-01-25 00:41:09,132 - util.py[DEBUG]: Read 15088 bytes from /var/lib/cloud/instance/obj.pkl
2018-01-25 00:41:09,135 - util.py[DEBUG]: Reading from /run/cloud-init/.instance-id (quiet=False)
2018-01-25 00:41:09,135 - util.py[DEBUG]: Read 9 bytes from /run/cloud-init/.instance-id
2018-01-25 00:41:09,135 - stages.py[DEBUG]: restored from cache with run check: DataSourceDigitalOcean
2018-01-25 00:41:09,135 - handlers.py[DEBUG]: finish: init-network/check-cache: SUCCESS: restored from cache with run check: DataSourceDigitalOcean
2018-01-25 00:41:09,135 - util.py[DEBUG]: Reading from /etc/cloud/cloud.cfg (quiet=False)
2018-01-25 00:41:09,136 - util.py[DEBUG]: Read 3001 bytes from /etc/cloud/cloud.cfg
2018-01-25 00:41:09,136 - util.py[DEBUG]: Attempting to load yaml from string of length 3001 with allowed root types (<class 'dict'>,)
2018-01-25 00:41:09,151 - util.py[DEBUG]: Reading from /etc/cloud/cloud.cfg.d/99-digitalocean.cfg (quiet=False)
2018-01-25 00:41:09,151 - util.py[DEBUG]: Read 168 bytes from /etc/cloud/cloud.cfg.d/99-digitalocean.cfg
2018-01-25 00:41:09,151 - util.py[DEBUG]: Attempting to load yaml from string of length 168 with allowed root types (<class 'dict'>,)
2018-01-25 00:41:09,152 - util.py[DEBUG]: Reading from /etc/cloud/cloud.cfg.d/90_dpkg.cfg (quiet=False)
2018-01-25 00:41:09,152 - util.py[DEBUG]: Read 238 bytes from /etc/cloud/cloud.cfg.d/90_dpkg.cfg
2018-01-25 00:41:09,152 - util.py[DEBUG]: Attempting to load yaml from string of length 238 with allowed root types (<class 'dict'>,)
2018-01-25 00:41:09,154 - util.py[DEBUG]: Reading from /etc/cloud/cloud.cfg.d/05_logging.cfg (quiet=False)
2018-01-25 00:41:09,154 - util.py[DEBUG]: Read 2057 bytes from /etc/cloud/cloud.cfg.d/05_logging.cfg
2018-01-25 00:41:09,154 - util.py[DEBUG]: Attempting to load yaml from string of length 2057 with allowed root types (<class 'dict'>,)
2018-01-25 00:41:09,159 - util.py[DEBUG]: Reading from /run/cloud-init/cloud.cfg (quiet=False)
2018-01-25 00:41:09,159 - util.py[DEBUG]: Read 53 bytes from /run/cloud-init/cloud.cfg
2018-01-25 00:41:09,159 - util.py[DEBUG]: Attempting to load yaml from string of length 53 with allowed root types (<class 'dict'>,)
2018-01-25 00:41:09,160 - util.py[DEBUG]: Attempting to load yaml from string of length 0 with allowed root types (<class 'dict'>,)
2018-01-25 00:41:09,160 - util.py[DEBUG]: load_yaml given empty string, returning default
2018-01-25 00:41:09,160 - util.py[DEBUG]: Attempting to remove /var/lib/cloud/instance
2018-01-25 00:41:09,161 - util.py[DEBUG]: Creating symbolic link from '/var/lib/cloud/instance' => '/var/lib/cloud/instances/80040526'
2018-01-25 00:41:09,161 - util.py[DEBUG]: Reading from /var/lib/cloud/instances/80040526/datasource (quiet=False)
2018-01-25 00:41:09,161 - util.py[DEBUG]: Read 47 bytes from /var/lib/cloud/instances/80040526/datasource
2018-01-25 00:41:09,161 - util.py[DEBUG]: Writing to /var/lib/cloud/instances/80040526/datasource - wb: [644] 47 bytes
2018-01-25 00:41:09,162 - util.py[DEBUG]: Writing to /var/lib/cloud/data/previous-datasource - wb: [644] 47 bytes
2018-01-25 00:41:09,163 - util.py[DEBUG]: Reading from /var/lib/cloud/data/instance-id (quiet=False)
2018-01-25 00:41:09,163 - util.py[DEBUG]: Read 9 bytes from /var/lib/cloud/data/instance-id
2018-01-25 00:41:09,163 - stages.py[DEBUG]: previous iid found to be 80040526
2018-01-25 00:41:09,163 - util.py[DEBUG]: Writing to /var/lib/cloud/data/instance-id - wb: [644] 9 bytes
2018-01-25 00:41:09,163 - util.py[DEBUG]: Writing to /run/cloud-init/.instance-id - wb: [644] 9 bytes
2018-01-25 00:41:09,164 - util.py[DEBUG]: Writing to /var/lib/cloud/data/previous-instance-id - wb: [644] 9 bytes
2018-01-25 00:41:09,165 - util.py[DEBUG]: Writing to /var/lib/cloud/instance/obj.pkl - wb: [400] 15170 bytes
2018-01-25 00:41:09,165 - main.py[DEBUG]: [net] init will now be targeting instance id: 80040526. new=False
2018-01-25 00:41:09,165 - util.py[DEBUG]: Reading from /etc/cloud/cloud.cfg (quiet=False)
2018-01-25 00:41:09,165 - util.py[DEBUG]: Read 3001 bytes from /etc/cloud/cloud.cfg
2018-01-25 00:41:09,166 - util.py[DEBUG]: Attempting to load yaml from string of length 3001 with allowed root types (<class 'dict'>,)
2018-01-25 00:41:09,180 - util.py[DEBUG]: Reading from /etc/cloud/cloud.cfg.d/99-digitalocean.cfg (quiet=False)
2018-01-25 00:41:09,180 - util.py[DEBUG]: Read 168 bytes from /etc/cloud/cloud.cfg.d/99-digitalocean.cfg
2018-01-25 00:41:09,180 - util.py[DEBUG]: Attempting to load yaml from string of length 168 with allowed root types (<class 'dict'>,)
2018-01-25 00:41:09,181 - util.py[DEBUG]: Reading from /etc/cloud/cloud.cfg.d/90_dpkg.cfg (quiet=False)
2018-01-25 00:41:09,181 - util.py[DEBUG]: Read 238 bytes from /etc/cloud/cloud.cfg.d/90_dpkg.cfg
2018-01-25 00:41:09,181 - util.py[DEBUG]: Attempting to load yaml from string of length 238 with allowed root types (<class 'dict'>,)
2018-01-25 00:41:09,183 - util.py[DEBUG]: Reading from /etc/cloud/cloud.cfg.d/05_logging.cfg (quiet=False)
2018-01-25 00:41:09,183 - util.py[DEBUG]: Read 2057 bytes from /etc/cloud/cloud.cfg.d/05_logging.cfg
2018-01-25 00:41:09,183 - util.py[DEBUG]: Attempting to load yaml from string of length 2057 with allowed root types (<class 'dict'>,)
2018-01-25 00:41:09,187 - util.py[DEBUG]: Reading from /run/cloud-init/cloud.cfg (quiet=False)
2018-01-25 00:41:09,188 - util.py[DEBUG]: Read 53 bytes from /run/cloud-init/cloud.cfg
2018-01-25 00:41:09,188 - util.py[DEBUG]: Attempting to load yaml from string of length 53 with allowed root types (<class 'dict'>,)
2018-01-25 00:41:09,188 - util.py[DEBUG]: Attempting to load yaml from string of length 0 with allowed root types (<class 'dict'>,)
2018-01-25 00:41:09,188 - util.py[DEBUG]: load_yaml given empty string, returning default
2018-01-25 00:41:09,189 - DataSourceDigitalOcean.py[DEBUG]: {'public': [{'anchor_ipv4': {'gateway': '10.46.0.1', 'netmask': '255.255.0.0', 'ip_address': '10.46.0.5'}, 'mac': '0e:43:e6:58:14:52', 'type': 'public', 'ipv4': {'gateway': '159.89.144.1', 'netmask': '255.255.240.0', 'ip_address': '159.89.146.218'}}]}
2018-01-25 00:41:09,189 - util.py[DEBUG]: Reading from /sys/class/net/eth0/addr_assign_type (quiet=False)
2018-01-25 00:41:09,189 - util.py[DEBUG]: Read 2 bytes from /sys/class/net/eth0/addr_assign_type
2018-01-25 00:41:09,190 - util.py[DEBUG]: Reading from /sys/class/net/eth0/uevent (quiet=False)
2018-01-25 00:41:09,190 - util.py[DEBUG]: Read 25 bytes from /sys/class/net/eth0/uevent
2018-01-25 00:41:09,190 - util.py[DEBUG]: Reading from /sys/class/net/eth0/address (quiet=False)
2018-01-25 00:41:09,190 - util.py[DEBUG]: Read 18 bytes from /sys/class/net/eth0/address
2018-01-25 00:41:09,190 - util.py[DEBUG]: Reading from /sys/class/net/eth0/device/device (quiet=False)
2018-01-25 00:41:09,190 - util.py[DEBUG]: Read 7 bytes from /sys/class/net/eth0/device/device
2018-01-25 00:41:09,190 - util.py[DEBUG]: Reading from /sys/class/net/lo/addr_assign_type (quiet=False)
2018-01-25 00:41:09,190 - util.py[DEBUG]: Read 2 bytes from /sys/class/net/lo/addr_assign_type
2018-01-25 00:41:09,190 - util.py[DEBUG]: Reading from /sys/class/net/lo/uevent (quiet=False)
2018-01-25 00:41:09,190 - util.py[DEBUG]: Read 23 bytes from /sys/class/net/lo/uevent
2018-01-25 00:41:09,190 - util.py[DEBUG]: Reading from /sys/class/net/lo/address (quiet=False)
2018-01-25 00:41:09,190 - util.py[DEBUG]: Read 18 bytes from /sys/class/net/lo/address
2018-01-25 00:41:09,191 - util.py[DEBUG]: Reading from /sys/class/net/lo/device/device (quiet=False)
2018-01-25 00:41:09,191 - digitalocean.py[DEBUG]: nic mapping: {'00:00:00:00:00:00': 'lo', '0e:43:e6:58:14:52': 'eth0'}
2018-01-25 00:41:09,191 - digitalocean.py[DEBUG]: considering {'anchor_ipv4': {'gateway': '10.46.0.1', 'netmask': '255.255.0.0', 'ip_address': '10.46.0.5'}, 'mac': '0e:43:e6:58:14:52', 'type': 'public', 'ipv4': {'gateway': '159.89.144.1', 'netmask': '255.255.240.0', 'ip_address': '159.89.146.218'}}
2018-01-25 00:41:09,191 - digitalocean.py[DEBUG]: Found interface '0e:43:e6:58:14:52' on 'eth0', which is not a public or private interface. Using default system naming.
2018-01-25 00:41:09,191 - digitalocean.py[DEBUG]: nic 'eth0' configuration: {'name': 'eth0', 'subnets': [{'address': '159.89.146.218', 'control': 'auto', 'netmask': '255.255.240.0', 'gateway': '159.89.144.1', 'type': 'static'}, {'address': '10.46.0.5', 'control': 'auto', 'netmask': '255.255.0.0', 'type': 'static'}], 'mac_address': '0e:43:e6:58:14:52', 'type': 'physical'}
2018-01-25 00:41:09,191 - digitalocean.py[DEBUG]: added dns servers: ['67.207.67.2', '67.207.67.3']
2018-01-25 00:41:09,191 - stages.py[DEBUG]: applying net config names for {'config': [{'name': 'eth0', 'subnets': [{'address': '159.89.146.218', 'control': 'auto', 'netmask': '255.255.240.0', 'gateway': '159.89.144.1', 'type': 'static'}, {'address': '10.46.0.5', 'control': 'auto', 'netmask': '255.255.0.0', 'type': 'static'}], 'mac_address': '0e:43:e6:58:14:52', 'type': 'physical'}, {'address': ['67.207.67.2', '67.207.67.3'], 'type': 'nameserver'}], 'version': 1}
2018-01-25 00:41:09,192 - stages.py[DEBUG]: Using distro class <class 'cloudinit.distros.ubuntu.Distro'>
2018-01-25 00:41:09,192 - util.py[DEBUG]: Reading from /sys/class/net/eth0/device/device (quiet=False)
2018-01-25 00:41:09,192 - util.py[DEBUG]: Read 7 bytes from /sys/class/net/eth0/device/device
2018-01-25 00:41:09,192 - util.py[DEBUG]: Reading from /sys/class/net/eth0/addr_assign_type (quiet=False)
2018-01-25 00:41:09,192 - util.py[DEBUG]: Read 2 bytes from /sys/class/net/eth0/addr_assign_type
2018-01-25 00:41:09,193 - util.py[DEBUG]: Reading from /sys/class/net/eth0/uevent (quiet=False)
2018-01-25 00:41:09,193 - util.py[DEBUG]: Read 25 bytes from /sys/class/net/eth0/uevent
2018-01-25 00:41:09,193 - util.py[DEBUG]: Reading from /sys/class/net/eth0/address (quiet=False)
2018-01-25 00:41:09,193 - util.py[DEBUG]: Read 18 bytes from /sys/class/net/eth0/address
2018-01-25 00:41:09,193 - util.py[DEBUG]: Reading from /sys/class/net/eth0/device/device (quiet=False)
2018-01-25 00:41:09,193 - util.py[DEBUG]: Read 7 bytes from /sys/class/net/eth0/device/device
2018-01-25 00:41:09,193 - util.py[DEBUG]: Reading from /sys/class/net/lo/addr_assign_type (quiet=False)
2018-01-25 00:41:09,193 - util.py[DEBUG]: Read 2 bytes from /sys/class/net/lo/addr_assign_type
2018-01-25 00:41:09,193 - util.py[DEBUG]: Reading from /sys/class/net/lo/uevent (quiet=False)
2018-01-25 00:41:09,193 - util.py[DEBUG]: Read 23 bytes from /sys/class/net/lo/uevent
2018-01-25 00:41:09,193 - util.py[DEBUG]: Reading from /sys/class/net/lo/address (quiet=False)
2018-01-25 00:41:09,193 - util.py[DEBUG]: Read 18 bytes from /sys/class/net/lo/address
2018-01-25 00:41:09,193 - util.py[DEBUG]: Reading from /sys/class/net/lo/device/device (quiet=False)
2018-01-25 00:41:09,193 - util.py[DEBUG]: Reading from /sys/class/net/eth0/operstate (quiet=False)
2018-01-25 00:41:09,194 - util.py[DEBUG]: Read 3 bytes from /sys/class/net/eth0/operstate
2018-01-25 00:41:09,194 - util.py[DEBUG]: Reading from /sys/class/net/lo/operstate (quiet=False)
2018-01-25 00:41:09,194 - util.py[DEBUG]: Read 8 bytes from /sys/class/net/lo/operstate
2018-01-25 00:41:09,194 - util.py[DEBUG]: Running command ['ip', '-6', 'addr', 'show', 'permanent', 'scope', 'global'] with allowed return codes [0] (shell=False, capture=True)
2018-01-25 00:41:09,196 - util.py[DEBUG]: Running command ['ip', '-4', 'addr', 'show'] with allowed return codes [0] (shell=False, capture=True)
2018-01-25 00:41:09,199 - __init__.py[DEBUG]: no work necessary for renaming of [['0e:43:e6:58:14:52', 'eth0', 'virtio_net', '0x0001']]
2018-01-25 00:41:09,199 - stages.py[DEBUG]: not a new instance. network config is not applied.
2018-01-25 00:41:09,199 - util.py[DEBUG]: Writing to /var/lib/cloud/instances/80040526/user-data.txt - wb: [600] 0 bytes
2018-01-25 00:41:09,202 - util.py[DEBUG]: Writing to /var/lib/cloud/instances/80040526/user-data.txt.i - wb: [600] 308 bytes
2018-01-25 00:41:09,203 - util.py[DEBUG]: Writing to /var/lib/cloud/instances/80040526/vendor-data.txt - wb: [600] 8700 bytes
2018-01-25 00:41:09,205 - util.py[DEBUG]: Attempting to load yaml from string of length 604 with allowed root types (<class 'dict'>,)
2018-01-25 00:41:09,210 - util.py[DEBUG]: Writing to /var/lib/cloud/instances/80040526/vendor-data.txt.i - wb: [600] 8721 bytes
2018-01-25 00:41:09,211 - util.py[DEBUG]: Writing to /var/lib/cloud/instances/80040526/sem/consume_data - wb: [644] 24 bytes
2018-01-25 00:41:09,211 - helpers.py[DEBUG]: Running consume_data using lock (<FileLock using file '/var/lib/cloud/instances/80040526/sem/consume_data'>)
2018-01-25 00:41:09,212 - handlers.py[DEBUG]: start: init-network/consume-user-data: reading and applying user-data
2018-01-25 00:41:09,212 - stages.py[DEBUG]: Added default handler for {'text/cloud-config-jsonp', 'text/cloud-config'} from CloudConfigPartHandler: [['text/cloud-config', 'text/cloud-config-jsonp']]
2018-01-25 00:41:09,212 - stages.py[DEBUG]: Added default handler for {'text/x-shellscript'} from ShellScriptPartHandler: [['text/x-shellscript']]
2018-01-25 00:41:09,212 - stages.py[DEBUG]: Added default handler for {'text/cloud-boothook'} from BootHookPartHandler: [['text/cloud-boothook']]
2018-01-25 00:41:09,212 - stages.py[DEBUG]: Added default handler for {'text/upstart-job'} from UpstartJobPartHandler: [['text/upstart-job']]
2018-01-25 00:41:09,213 - __init__.py[DEBUG]: Calling handler CloudConfigPartHandler: [['text/cloud-config', 'text/cloud-config-jsonp']] (__begin__, None, 3) with frequency once-per-instance
2018-01-25 00:41:09,213 - __init__.py[DEBUG]: Calling handler UpstartJobPartHandler: [['text/upstart-job']] (__begin__, None, 2) with frequency once-per-instance
2018-01-25 00:41:09,213 - __init__.py[DEBUG]: Calling handler BootHookPartHandler: [['text/cloud-boothook']] (__begin__, None, 2) with frequency once-per-instance
2018-01-25 00:41:09,213 - __init__.py[DEBUG]: Calling handler ShellScriptPartHandler: [['text/x-shellscript']] (__begin__, None, 2) with frequency once-per-instance
2018-01-25 00:41:09,213 - __init__.py[DEBUG]: {'Content-Type': 'text/x-not-multipart', 'MIME-Version': '1.0', 'Content-Disposition': 'attachment; filename="part-001"'}
2018-01-25 00:41:09,213 - __init__.py[DEBUG]: Empty payload of type text/x-not-multipart
2018-01-25 00:41:09,213 - __init__.py[DEBUG]: Calling handler CloudConfigPartHandler: [['text/cloud-config', 'text/cloud-config-jsonp']] (__end__, None, 3) with frequency once-per-instance
2018-01-25 00:41:09,213 - util.py[DEBUG]: Writing to /var/lib/cloud/instances/80040526/cloud-config.txt - wb: [600] 0 bytes
2018-01-25 00:41:09,214 - __init__.py[DEBUG]: Calling handler UpstartJobPartHandler: [['text/upstart-job']] (__end__, None, 2) with frequency once-per-instance
2018-01-25 00:41:09,214 - __init__.py[DEBUG]: Calling handler BootHookPartHandler: [['text/cloud-boothook']] (__end__, None, 2) with frequency once-per-instance
2018-01-25 00:41:09,214 - __init__.py[DEBUG]: Calling handler ShellScriptPartHandler: [['text/x-shellscript']] (__end__, None, 2) with frequency once-per-instance
2018-01-25 00:41:09,215 - handlers.py[DEBUG]: finish: init-network/consume-user-data: SUCCESS: reading and applying user-data
2018-01-25 00:41:09,215 - handlers.py[DEBUG]: start: init-network/consume-vendor-data: reading and applying vendor-data
2018-01-25 00:41:09,215 - util.py[DEBUG]: Reading from /var/lib/cloud/instance/cloud-config.txt (quiet=False)
2018-01-25 00:41:09,215 - util.py[DEBUG]: Read 0 bytes from /var/lib/cloud/instance/cloud-config.txt
2018-01-25 00:41:09,216 - util.py[DEBUG]: Attempting to load yaml from string of length 0 with allowed root types (<class 'dict'>,)
2018-01-25 00:41:09,216 - util.py[DEBUG]: load_yaml given empty string, returning default
2018-01-25 00:41:09,216 - stages.py[DEBUG]: vendor data will be consumed. disabled_handlers=None
2018-01-25 00:41:09,217 - stages.py[DEBUG]: Added default handler for {'text/cloud-config-jsonp', 'text/cloud-config'} from CloudConfigPartHandler: [['text/cloud-config', 'text/cloud-config-jsonp']]
2018-01-25 00:41:09,217 - stages.py[DEBUG]: Added default handler for {'text/x-shellscript'} from ShellScriptPartHandler: [['text/x-shellscript']]
2018-01-25 00:41:09,217 - stages.py[DEBUG]: Added default handler for {'text/cloud-boothook'} from BootHookPartHandler: [['text/cloud-boothook']]
2018-01-25 00:41:09,217 - stages.py[DEBUG]: Added default handler for {'text/upstart-job'} from UpstartJobPartHandler: [['text/upstart-job']]
2018-01-25 00:41:09,218 - __init__.py[DEBUG]: Calling handler CloudConfigPartHandler: [['text/cloud-config', 'text/cloud-config-jsonp']] (__begin__, None, 3) with frequency once-per-instance
2018-01-25 00:41:09,218 - __init__.py[DEBUG]: Calling handler UpstartJobPartHandler: [['text/upstart-job']] (__begin__, None, 2) with frequency once-per-instance
2018-01-25 00:41:09,218 - __init__.py[DEBUG]: Calling handler BootHookPartHandler: [['text/cloud-boothook']] (__begin__, None, 2) with frequency once-per-instance
2018-01-25 00:41:09,218 - __init__.py[DEBUG]: Calling handler ShellScriptPartHandler: [['text/x-shellscript']] (__begin__, None, 2) with frequency once-per-instance
2018-01-25 00:41:09,218 - __init__.py[DEBUG]: {'Content-Transfer-Encoding': '7bit', 'Content-Type': 'text/cloud-config; charset="us-ascii"', 'MIME-Version': '1.0', 'Content-Disposition': 'attachment; filename="cloud-config"'}
2018-01-25 00:41:09,219 - __init__.py[DEBUG]: Calling handler CloudConfigPartHandler: [['text/cloud-config', 'text/cloud-config-jsonp']] (text/cloud-config, cloud-config, 3) with frequency once-per-instance
2018-01-25 00:41:09,219 - util.py[DEBUG]: Attempting to load yaml from string of length 604 with allowed root types (<class 'dict'>,)
2018-01-25 00:41:09,223 - cloud_config.py[DEBUG]: Merging by applying [('dict', ['replace']), ('list', []), ('str', [])]
2018-01-25 00:41:09,223 - __init__.py[DEBUG]: {'Content-Transfer-Encoding': '7bit', 'Content-Type': 'text/cloud-boothook; charset="us-ascii"', 'MIME-Version': '1.0', 'Content-Disposition': 'attachment; filename="entropy-seed"'}
2018-01-25 00:41:09,223 - __init__.py[DEBUG]: Calling handler BootHookPartHandler: [['text/cloud-boothook']] (text/cloud-boothook, entropy-seed, 2) with frequency once-per-instance
2018-01-25 00:41:09,224 - util.py[DEBUG]: Writing to /var/lib/cloud/instances/80040526/boothooks/entropy-seed - wb: [700] 4299 bytes
2018-01-25 00:41:09,224 - util.py[DEBUG]: Running command ['/var/lib/cloud/instances/80040526/boothooks/entropy-seed'] with allowed return codes [0] (shell=False, capture=True)
2018-01-25 00:41:09,231 - __init__.py[DEBUG]: {'Content-Transfer-Encoding': '7bit', 'Content-Type': 'text/cloud-boothook; charset="us-ascii"', 'MIME-Version': '1.0', 'Content-Disposition': 'attachment; filename="digitalocean_fixups"'}
2018-01-25 00:41:09,231 - __init__.py[DEBUG]: Calling handler BootHookPartHandler: [['text/cloud-boothook']] (text/cloud-boothook, digitalocean_fixups, 2) with frequency once-per-instance
2018-01-25 00:41:09,231 - util.py[DEBUG]: Writing to /var/lib/cloud/instances/80040526/boothooks/digitalocean_fixups - wb: [700] 3046 bytes
2018-01-25 00:41:09,232 - util.py[DEBUG]: Running command ['/var/lib/cloud/instances/80040526/boothooks/digitalocean_fixups'] with allowed return codes [0] (shell=False, capture=True)
2018-01-25 00:41:09,242 - __init__.py[DEBUG]: Calling handler CloudConfigPartHandler: [['text/cloud-config', 'text/cloud-config-jsonp']] (__end__, None, 3) with frequency once-per-instance
2018-01-25 00:41:09,244 - util.py[DEBUG]: Writing to /var/lib/cloud/instances/80040526/vendor-cloud-config.txt - wb: [600] 548 bytes
2018-01-25 00:41:09,245 - __init__.py[DEBUG]: Calling handler UpstartJobPartHandler: [['text/upstart-job']] (__end__, None, 2) with frequency once-per-instance
2018-01-25 00:41:09,245 - __init__.py[DEBUG]: Calling handler BootHookPartHandler: [['text/cloud-boothook']] (__end__, None, 2) with frequency once-per-instance
2018-01-25 00:41:09,246 - __init__.py[DEBUG]: Calling handler ShellScriptPartHandler: [['text/x-shellscript']] (__end__, None, 2) with frequency once-per-instance
2018-01-25 00:41:09,246 - handlers.py[DEBUG]: finish: init-network/consume-vendor-data: SUCCESS: reading and applying vendor-data
2018-01-25 00:41:09,246 - util.py[DEBUG]: Reading from /etc/cloud/cloud.cfg (quiet=False)
2018-01-25 00:41:09,246 - util.py[DEBUG]: Read 3001 bytes from /etc/cloud/cloud.cfg
2018-01-25 00:41:09,246 - util.py[DEBUG]: Attempting to load yaml from string of length 3001 with allowed root types (<class 'dict'>,)
2018-01-25 00:41:09,260 - util.py[DEBUG]: Reading from /etc/cloud/cloud.cfg.d/99-digitalocean.cfg (quiet=False)
2018-01-25 00:41:09,260 - util.py[DEBUG]: Read 168 bytes from /etc/cloud/cloud.cfg.d/99-digitalocean.cfg
2018-01-25 00:41:09,260 - util.py[DEBUG]: Attempting to load yaml from string of length 168 with allowed root types (<class 'dict'>,)
2018-01-25 00:41:09,261 - util.py[DEBUG]: Reading from /etc/cloud/cloud.cfg.d/90_dpkg.cfg (quiet=False)
2018-01-25 00:41:09,261 - util.py[DEBUG]: Read 238 bytes from /etc/cloud/cloud.cfg.d/90_dpkg.cfg
2018-01-25 00:41:09,261 - util.py[DEBUG]: Attempting to load yaml from string of length 238 with allowed root types (<class 'dict'>,)
2018-01-25 00:41:09,263 - util.py[DEBUG]: Reading from /etc/cloud/cloud.cfg.d/90-digitalocean.cfg (quiet=False)
2018-01-25 00:41:09,263 - util.py[DEBUG]: Read 3511 bytes from /etc/cloud/cloud.cfg.d/90-digitalocean.cfg
2018-01-25 00:41:09,263 - util.py[DEBUG]: Attempting to load yaml from string of length 3511 with allowed root types (<class 'dict'>,)
2018-01-25 00:41:09,277 - util.py[DEBUG]: Reading from /etc/cloud/cloud.cfg.d/05_logging.cfg (quiet=False)
2018-01-25 00:41:09,277 - util.py[DEBUG]: Read 2057 bytes from /etc/cloud/cloud.cfg.d/05_logging.cfg
2018-01-25 00:41:09,277 - util.py[DEBUG]: Attempting to load yaml from string of length 2057 with allowed root types (<class 'dict'>,)
2018-01-25 00:41:09,281 - util.py[DEBUG]: Reading from /run/cloud-init/cloud.cfg (quiet=False)
2018-01-25 00:41:09,281 - util.py[DEBUG]: Read 53 bytes from /run/cloud-init/cloud.cfg
2018-01-25 00:41:09,281 - util.py[DEBUG]: Attempting to load yaml from string of length 53 with allowed root types (<class 'dict'>,)
2018-01-25 00:41:09,282 - util.py[DEBUG]: Attempting to load yaml from string of length 0 with allowed root types (<class 'dict'>,)
2018-01-25 00:41:09,282 - util.py[DEBUG]: load_yaml given empty string, returning default
2018-01-25 00:41:09,283 - util.py[DEBUG]: Reading from /var/lib/cloud/instance/cloud-config.txt (quiet=False)
2018-01-25 00:41:09,283 - util.py[DEBUG]: Read 0 bytes from /var/lib/cloud/instance/cloud-config.txt
2018-01-25 00:41:09,283 - util.py[DEBUG]: Attempting to load yaml from string of length 0 with allowed root types (<class 'dict'>,)
2018-01-25 00:41:09,283 - util.py[DEBUG]: load_yaml given empty string, returning default
2018-01-25 00:41:09,283 - util.py[DEBUG]: Reading from /var/lib/cloud/instance/vendor-cloud-config.txt (quiet=False)
2018-01-25 00:41:09,283 - util.py[DEBUG]: Read 548 bytes from /var/lib/cloud/instance/vendor-cloud-config.txt
2018-01-25 00:41:09,283 - util.py[DEBUG]: Attempting to load yaml from string of length 548 with allowed root types (<class 'dict'>,)
2018-01-25 00:41:09,287 - util.py[DEBUG]: Reading from /var/lib/cloud/instance/cloud-config.txt (quiet=False)
2018-01-25 00:41:09,287 - util.py[DEBUG]: Read 0 bytes from /var/lib/cloud/instance/cloud-config.txt
2018-01-25 00:41:09,287 - util.py[DEBUG]: Attempting to load yaml from string of length 0 with allowed root types (<class 'dict'>,)
2018-01-25 00:41:09,288 - util.py[DEBUG]: load_yaml given empty string, returning default
2018-01-25 00:41:09,288 - util.py[DEBUG]: Reading from /var/lib/cloud/instance/vendor-cloud-config.txt (quiet=False)
2018-01-25 00:41:09,288 - util.py[DEBUG]: Read 548 bytes from /var/lib/cloud/instance/vendor-cloud-config.txt
2018-01-25 00:41:09,288 - util.py[DEBUG]: Attempting to load yaml from string of length 548 with allowed root types (<class 'dict'>,)
2018-01-25 00:41:09,294 - util.py[DEBUG]: Writing to /var/lib/cloud/instance/obj.pkl - wb: [400] 23649 bytes
2018-01-25 00:41:09,295 - main.py[DEBUG]: used datasource 'DataSourceDigitalOcean' from 'DigitalOcean' was in di_report's list: ['DigitalOcean', 'None']
2018-01-25 00:41:09,346 - stages.py[DEBUG]: Using distro class <class 'cloudinit.distros.ubuntu.Distro'>
2018-01-25 00:41:09,347 - stages.py[DEBUG]: Running module migrator (<module 'cloudinit.config.cc_migrator' from '/usr/lib/python3/dist-packages/cloudinit/config/cc_migrator.py'>) with frequency always
2018-01-25 00:41:09,348 - handlers.py[DEBUG]: start: init-network/config-migrator: running config-migrator with frequency always
2018-01-25 00:41:09,348 - helpers.py[DEBUG]: Running config-migrator using lock (<cloudinit.helpers.DummyLock object at 0x7fbf1ff9c7b8>)
2018-01-25 00:41:09,348 - cc_migrator.py[DEBUG]: Migrated 0 semaphore files to there canonicalized names
2018-01-25 00:41:09,348 - handlers.py[DEBUG]: finish: init-network/config-migrator: SUCCESS: config-migrator ran successfully
2018-01-25 00:41:09,348 - stages.py[DEBUG]: Running module seed_random (<module 'cloudinit.config.cc_seed_random' from '/usr/lib/python3/dist-packages/cloudinit/config/cc_seed_random.py'>) with frequency once-per-instance
2018-01-25 00:41:09,349 - handlers.py[DEBUG]: start: init-network/config-seed_random: running config-seed_random with frequency once-per-instance
2018-01-25 00:41:09,349 - util.py[DEBUG]: Writing to /var/lib/cloud/instances/80040526/sem/config_seed_random - wb: [644] 24 bytes
2018-01-25 00:41:09,349 - helpers.py[DEBUG]: Running config-seed_random using lock (<FileLock using file '/var/lib/cloud/instances/80040526/sem/config_seed_random'>)
2018-01-25 00:41:09,350 - cc_seed_random.py[DEBUG]: no command provided
2018-01-25 00:41:09,350 - handlers.py[DEBUG]: finish: init-network/config-seed_random: SUCCESS: config-seed_random ran successfully
2018-01-25 00:41:09,350 - stages.py[DEBUG]: Running module bootcmd (<module 'cloudinit.config.cc_bootcmd' from '/usr/lib/python3/dist-packages/cloudinit/config/cc_bootcmd.py'>) with frequency always
2018-01-25 00:41:09,350 - handlers.py[DEBUG]: start: init-network/config-bootcmd: running config-bootcmd with frequency always
2018-01-25 00:41:09,350 - helpers.py[DEBUG]: Running config-bootcmd using lock (<cloudinit.helpers.DummyLock object at 0x7fbf1ff95128>)
2018-01-25 00:41:09,350 - cc_bootcmd.py[DEBUG]: Skipping module named bootcmd, no 'bootcmd' key in configuration
2018-01-25 00:41:09,351 - handlers.py[DEBUG]: finish: init-network/config-bootcmd: SUCCESS: config-bootcmd ran successfully
2018-01-25 00:41:09,351 - stages.py[DEBUG]: Running module write-files (<module 'cloudinit.config.cc_write_files' from '/usr/lib/python3/dist-packages/cloudinit/config/cc_write_files.py'>) with frequency once-per-instance
2018-01-25 00:41:09,351 - handlers.py[DEBUG]: start: init-network/config-write-files: running config-write-files with frequency once-per-instance
2018-01-25 00:41:09,351 - util.py[DEBUG]: Writing to /var/lib/cloud/instances/80040526/sem/config_write_files - wb: [644] 24 bytes
2018-01-25 00:41:09,352 - helpers.py[DEBUG]: Running config-write-files using lock (<FileLock using file '/var/lib/cloud/instances/80040526/sem/config_write_files'>)
2018-01-25 00:41:09,352 - cc_write_files.py[DEBUG]: Skipping module named write-files, no/empty 'write_files' key in configuration
2018-01-25 00:41:09,352 - handlers.py[DEBUG]: finish: init-network/config-write-files: SUCCESS: config-write-files ran successfully
2018-01-25 00:41:09,352 - stages.py[DEBUG]: Running module growpart (<module 'cloudinit.config.cc_growpart' from '/usr/lib/python3/dist-packages/cloudinit/config/cc_growpart.py'>) with frequency always
2018-01-25 00:41:09,352 - handlers.py[DEBUG]: start: init-network/config-growpart: running config-growpart with frequency always
2018-01-25 00:41:09,352 - helpers.py[DEBUG]: Running config-growpart using lock (<cloudinit.helpers.DummyLock object at 0x7fbf1ff95b38>)
2018-01-25 00:41:09,352 - cc_growpart.py[DEBUG]: No 'growpart' entry in cfg.  Using default: {'ignore_growroot_disabled': False, 'mode': 'auto', 'devices': ['/']}
2018-01-25 00:41:09,353 - util.py[DEBUG]: Running command ['growpart', '--help'] with allowed return codes [0] (shell=False, capture=True)
2018-01-25 00:41:09,357 - util.py[DEBUG]: Reading from /proc/1194/mountinfo (quiet=False)
2018-01-25 00:41:09,357 - util.py[DEBUG]: Read 2773 bytes from /proc/1194/mountinfo
2018-01-25 00:41:09,357 - util.py[DEBUG]: Running command ['systemd-detect-virt', '--quiet', '--container'] with allowed return codes [0] (shell=False, capture=True)
2018-01-25 00:41:09,360 - util.py[DEBUG]: Running command ['running-in-container'] with allowed return codes [0] (shell=False, capture=True)
2018-01-25 00:41:09,361 - util.py[DEBUG]: Running command ['lxc-is-container'] with allowed return codes [0] (shell=False, capture=True)
2018-01-25 00:41:09,363 - util.py[DEBUG]: Reading from /proc/1/environ (quiet=False)
2018-01-25 00:41:09,363 - util.py[DEBUG]: Read 153 bytes from /proc/1/environ
2018-01-25 00:41:09,363 - util.py[DEBUG]: Reading from /proc/self/status (quiet=False)
2018-01-25 00:41:09,363 - util.py[DEBUG]: Read 896 bytes from /proc/self/status
2018-01-25 00:41:09,367 - util.py[DEBUG]: Reading from /sys/class/block/vda1/partition (quiet=False)
2018-01-25 00:41:09,367 - util.py[DEBUG]: Read 2 bytes from /sys/class/block/vda1/partition
2018-01-25 00:41:09,367 - util.py[DEBUG]: Reading from /sys/devices/pci0000:00/0000:00:05.0/virtio2/block/vda/dev (quiet=False)
2018-01-25 00:41:09,368 - util.py[DEBUG]: Read 6 bytes from /sys/devices/pci0000:00/0000:00:05.0/virtio2/block/vda/dev
2018-01-25 00:41:09,368 - util.py[DEBUG]: Running command ['growpart', '--dry-run', '/dev/vda', '1'] with allowed return codes [0] (shell=False, capture=True)
2018-01-25 00:41:09,395 - util.py[DEBUG]: Running command ['growpart', '/dev/vda', '1'] with allowed return codes [0] (shell=False, capture=True)
2018-01-25 00:41:09,436 - util.py[DEBUG]: resize_devices took 0.079 seconds
2018-01-25 00:41:09,436 - cc_growpart.py[INFO]: '/' resized: changed (/dev/vda, 1) from 2244984320 to 171682283008
2018-01-25 00:41:09,436 - handlers.py[DEBUG]: finish: init-network/config-growpart: SUCCESS: config-growpart ran successfully
2018-01-25 00:41:09,436 - stages.py[DEBUG]: Running module resizefs (<module 'cloudinit.config.cc_resizefs' from '/usr/lib/python3/dist-packages/cloudinit/config/cc_resizefs.py'>) with frequency always
2018-01-25 00:41:09,437 - handlers.py[DEBUG]: start: init-network/config-resizefs: running config-resizefs with frequency always
2018-01-25 00:41:09,437 - helpers.py[DEBUG]: Running config-resizefs using lock (<cloudinit.helpers.DummyLock object at 0x7fbf1ff959b0>)
2018-01-25 00:41:09,438 - schema.py[DEBUG]: Ignoring schema validation. python-jsonschema is not present
2018-01-25 00:41:09,438 - util.py[DEBUG]: Reading from /proc/1194/mountinfo (quiet=False)
2018-01-25 00:41:09,438 - util.py[DEBUG]: Read 2773 bytes from /proc/1194/mountinfo
2018-01-25 00:41:09,438 - cc_resizefs.py[DEBUG]: resize_info: dev=/dev/vda1 mnt_point=/ path=/
2018-01-25 00:41:09,438 - util.py[DEBUG]: Running command ['systemd-detect-virt', '--quiet', '--container'] with allowed return codes [0] (shell=False, capture=True)
2018-01-25 00:41:09,443 - util.py[DEBUG]: Running command ['running-in-container'] with allowed return codes [0] (shell=False, capture=True)
2018-01-25 00:41:09,445 - util.py[DEBUG]: Running command ['lxc-is-container'] with allowed return codes [0] (shell=False, capture=True)
2018-01-25 00:41:09,447 - util.py[DEBUG]: Reading from /proc/1/environ (quiet=False)
2018-01-25 00:41:09,447 - util.py[DEBUG]: Read 153 bytes from /proc/1/environ
2018-01-25 00:41:09,447 - util.py[DEBUG]: Reading from /proc/self/status (quiet=False)
2018-01-25 00:41:09,447 - util.py[DEBUG]: Read 897 bytes from /proc/self/status
2018-01-25 00:41:09,447 - cc_resizefs.py[DEBUG]: Resizing / (ext4) using resize2fs /dev/vda1
2018-01-25 00:41:09,447 - util.py[DEBUG]: Running command ('resize2fs', '/dev/vda1') with allowed return codes [0] (shell=False, capture=True)
2018-01-25 00:41:09,496 - util.py[DEBUG]: Resizing took 0.049 seconds
2018-01-25 00:41:09,496 - cc_resizefs.py[DEBUG]: Resized root filesystem (type=ext4, val=True)
2018-01-25 00:41:09,497 - handlers.py[DEBUG]: finish: init-network/config-resizefs: SUCCESS: config-resizefs ran successfully
2018-01-25 00:41:09,497 - stages.py[DEBUG]: Running module disk_setup (<module 'cloudinit.config.cc_disk_setup' from '/usr/lib/python3/dist-packages/cloudinit/config/cc_disk_setup.py'>) with frequency once-per-instance
2018-01-25 00:41:09,497 - handlers.py[DEBUG]: start: init-network/config-disk_setup: running config-disk_setup with frequency once-per-instance
2018-01-25 00:41:09,498 - util.py[DEBUG]: Writing to /var/lib/cloud/instances/80040526/sem/config_disk_setup - wb: [644] 25 bytes
2018-01-25 00:41:09,498 - helpers.py[DEBUG]: Running config-disk_setup using lock (<FileLock using file '/var/lib/cloud/instances/80040526/sem/config_disk_setup'>)
2018-01-25 00:41:09,499 - handlers.py[DEBUG]: finish: init-network/config-disk_setup: SUCCESS: config-disk_setup ran successfully
2018-01-25 00:41:09,499 - stages.py[DEBUG]: Running module mounts (<module 'cloudinit.config.cc_mounts' from '/usr/lib/python3/dist-packages/cloudinit/config/cc_mounts.py'>) with frequency once-per-instance
2018-01-25 00:41:09,499 - handlers.py[DEBUG]: start: init-network/config-mounts: running config-mounts with frequency once-per-instance
2018-01-25 00:41:09,499 - util.py[DEBUG]: Writing to /var/lib/cloud/instances/80040526/sem/config_mounts - wb: [644] 25 bytes
2018-01-25 00:41:09,500 - helpers.py[DEBUG]: Running config-mounts using lock (<FileLock using file '/var/lib/cloud/instances/80040526/sem/config_mounts'>)
2018-01-25 00:41:09,500 - cc_mounts.py[DEBUG]: mounts configuration is []
2018-01-25 00:41:09,500 - cc_mounts.py[DEBUG]: Attempting to determine the real name of ephemeral0
2018-01-25 00:41:09,500 - cc_mounts.py[DEBUG]: Ignoring nonexistant default named mount ephemeral0
2018-01-25 00:41:09,500 - cc_mounts.py[DEBUG]: Attempting to determine the real name of swap
2018-01-25 00:41:09,500 - cc_mounts.py[DEBUG]: Ignoring nonexistant default named mount swap
2018-01-25 00:41:09,500 - cc_mounts.py[DEBUG]: no need to setup swap
2018-01-25 00:41:09,500 - cc_mounts.py[DEBUG]: No modifications to fstab needed.
2018-01-25 00:41:09,501 - handlers.py[DEBUG]: finish: init-network/config-mounts: SUCCESS: config-mounts ran successfully
2018-01-25 00:41:09,501 - stages.py[DEBUG]: Running module set_hostname (<module 'cloudinit.config.cc_set_hostname' from '/usr/lib/python3/dist-packages/cloudinit/config/cc_set_hostname.py'>) with frequency once-per-instance
2018-01-25 00:41:09,501 - handlers.py[DEBUG]: start: init-network/config-set_hostname: running config-set_hostname with frequency once-per-instance
2018-01-25 00:41:09,501 - util.py[DEBUG]: Writing to /var/lib/cloud/instances/80040526/sem/config_set_hostname - wb: [644] 25 bytes
2018-01-25 00:41:09,502 - helpers.py[DEBUG]: Running config-set_hostname using lock (<FileLock using file '/var/lib/cloud/instances/80040526/sem/config_set_hostname'>)
2018-01-25 00:41:09,502 - cc_set_hostname.py[DEBUG]: Setting the hostname to polyubuntu (polyubuntu)
2018-01-25 00:41:09,502 - util.py[DEBUG]: Reading from /etc/hostname (quiet=False)
2018-01-25 00:41:09,502 - util.py[DEBUG]: Read 7 bytes from /etc/hostname
2018-01-25 00:41:09,502 - util.py[DEBUG]: Writing to /etc/hostname - wb: [644] 11 bytes
2018-01-25 00:41:09,503 - __init__.py[DEBUG]: Non-persistently setting the system hostname to polyubuntu
2018-01-25 00:41:09,503 - util.py[DEBUG]: Running command ['hostname', 'polyubuntu'] with allowed return codes [0] (shell=False, capture=True)
2018-01-25 00:41:09,506 - handlers.py[DEBUG]: finish: init-network/config-set_hostname: SUCCESS: config-set_hostname ran successfully
2018-01-25 00:41:09,506 - stages.py[DEBUG]: Running module update_hostname (<module 'cloudinit.config.cc_update_hostname' from '/usr/lib/python3/dist-packages/cloudinit/config/cc_update_hostname.py'>) with frequency always
2018-01-25 00:41:09,507 - handlers.py[DEBUG]: start: init-network/config-update_hostname: running config-update_hostname with frequency always
2018-01-25 00:41:09,507 - helpers.py[DEBUG]: Running config-update_hostname using lock (<cloudinit.helpers.DummyLock object at 0x7fbf1ff95ef0>)
2018-01-25 00:41:09,507 - cc_update_hostname.py[DEBUG]: Updating hostname to polyubuntu (polyubuntu)
2018-01-25 00:41:09,507 - util.py[DEBUG]: Reading from /etc/hostname (quiet=False)
2018-01-25 00:41:09,508 - util.py[DEBUG]: Read 11 bytes from /etc/hostname
2018-01-25 00:41:09,508 - __init__.py[DEBUG]: Attempting to update hostname to polyubuntu in 1 files
2018-01-25 00:41:09,508 - util.py[DEBUG]: Reading from /var/lib/cloud/data/previous-hostname (quiet=False)
2018-01-25 00:41:09,508 - util.py[DEBUG]: Writing to /var/lib/cloud/data/previous-hostname - wb: [644] 11 bytes
2018-01-25 00:41:09,509 - handlers.py[DEBUG]: finish: init-network/config-update_hostname: SUCCESS: config-update_hostname ran successfully
2018-01-25 00:41:09,509 - stages.py[DEBUG]: Running module update_etc_hosts (<module 'cloudinit.config.cc_update_etc_hosts' from '/usr/lib/python3/dist-packages/cloudinit/config/cc_update_etc_hosts.py'>) with frequency once-per-instance
2018-01-25 00:41:09,509 - handlers.py[DEBUG]: start: init-network/config-update_etc_hosts: running config-update_etc_hosts with frequency once-per-instance
2018-01-25 00:41:09,509 - util.py[DEBUG]: Writing to /var/lib/cloud/instances/80040526/sem/config_update_etc_hosts - wb: [644] 24 bytes
2018-01-25 00:41:09,510 - helpers.py[DEBUG]: Running config-update_etc_hosts using lock (<FileLock using file '/var/lib/cloud/instances/80040526/sem/config_update_etc_hosts'>)
2018-01-25 00:41:09,511 - util.py[DEBUG]: Reading from /etc/cloud/templates/hosts.debian.tmpl (quiet=False)
2018-01-25 00:41:09,511 - util.py[DEBUG]: Read 901 bytes from /etc/cloud/templates/hosts.debian.tmpl
2018-01-25 00:41:09,511 - templater.py[DEBUG]: Rendering content of '/etc/cloud/templates/hosts.debian.tmpl' using renderer jinja
2018-01-25 00:41:09,515 - util.py[DEBUG]: Writing to /etc/hosts - wb: [644] 603 bytes
2018-01-25 00:41:09,515 - handlers.py[DEBUG]: finish: init-network/config-update_etc_hosts: SUCCESS: config-update_etc_hosts ran successfully
2018-01-25 00:41:09,516 - stages.py[DEBUG]: Running module ca-certs (<module 'cloudinit.config.cc_ca_certs' from '/usr/lib/python3/dist-packages/cloudinit/config/cc_ca_certs.py'>) with frequency once-per-instance
2018-01-25 00:41:09,516 - handlers.py[DEBUG]: start: init-network/config-ca-certs: running config-ca-certs with frequency once-per-instance
2018-01-25 00:41:09,516 - util.py[DEBUG]: Writing to /var/lib/cloud/instances/80040526/sem/config_ca_certs - wb: [644] 25 bytes
2018-01-25 00:41:09,517 - helpers.py[DEBUG]: Running config-ca-certs using lock (<FileLock using file '/var/lib/cloud/instances/80040526/sem/config_ca_certs'>)
2018-01-25 00:41:09,517 - cc_ca_certs.py[DEBUG]: Skipping module named ca-certs, no 'ca-certs' key in configuration
2018-01-25 00:41:09,517 - handlers.py[DEBUG]: finish: init-network/config-ca-certs: SUCCESS: config-ca-certs ran successfully
2018-01-25 00:41:09,517 - stages.py[DEBUG]: Running module rsyslog (<module 'cloudinit.config.cc_rsyslog' from '/usr/lib/python3/dist-packages/cloudinit/config/cc_rsyslog.py'>) with frequency once-per-instance
2018-01-25 00:41:09,517 - handlers.py[DEBUG]: start: init-network/config-rsyslog: running config-rsyslog with frequency once-per-instance
2018-01-25 00:41:09,517 - util.py[DEBUG]: Writing to /var/lib/cloud/instances/80040526/sem/config_rsyslog - wb: [644] 24 bytes
2018-01-25 00:41:09,518 - helpers.py[DEBUG]: Running config-rsyslog using lock (<FileLock using file '/var/lib/cloud/instances/80040526/sem/config_rsyslog'>)
2018-01-25 00:41:09,518 - cc_rsyslog.py[DEBUG]: Skipping module named rsyslog, no 'rsyslog' key in configuration
2018-01-25 00:41:09,518 - handlers.py[DEBUG]: finish: init-network/config-rsyslog: SUCCESS: config-rsyslog ran successfully
2018-01-25 00:41:09,518 - stages.py[DEBUG]: Running module users-groups (<module 'cloudinit.config.cc_users_groups' from '/usr/lib/python3/dist-packages/cloudinit/config/cc_users_groups.py'>) with frequency once-per-instance
2018-01-25 00:41:09,518 - handlers.py[DEBUG]: start: init-network/config-users-groups: running config-users-groups with frequency once-per-instance
2018-01-25 00:41:09,519 - util.py[DEBUG]: Writing to /var/lib/cloud/instances/80040526/sem/config_users_groups - wb: [644] 25 bytes
2018-01-25 00:41:09,519 - helpers.py[DEBUG]: Running config-users-groups using lock (<FileLock using file '/var/lib/cloud/instances/80040526/sem/config_users_groups'>)
2018-01-25 00:41:09,519 - __init__.py[INFO]: User root already exists, skipping.
2018-01-25 00:41:09,520 - util.py[DEBUG]: Reading from /etc/sudoers (quiet=False)
2018-01-25 00:41:09,520 - util.py[DEBUG]: Read 755 bytes from /etc/sudoers
2018-01-25 00:41:09,521 - util.py[DEBUG]: Writing to /etc/sudoers.d/90-cloud-init-users - wb: [440] 118 bytes
2018-01-25 00:41:09,521 - handlers.py[DEBUG]: finish: init-network/config-users-groups: SUCCESS: config-users-groups ran successfully
2018-01-25 00:41:09,521 - stages.py[DEBUG]: Running module ssh (<module 'cloudinit.config.cc_ssh' from '/usr/lib/python3/dist-packages/cloudinit/config/cc_ssh.py'>) with frequency once-per-instance
2018-01-25 00:41:09,521 - handlers.py[DEBUG]: start: init-network/config-ssh: running config-ssh with frequency once-per-instance
2018-01-25 00:41:09,522 - util.py[DEBUG]: Writing to /var/lib/cloud/instances/80040526/sem/config_ssh - wb: [644] 25 bytes
2018-01-25 00:41:09,522 - helpers.py[DEBUG]: Running config-ssh using lock (<FileLock using file '/var/lib/cloud/instances/80040526/sem/config_ssh'>)
2018-01-25 00:41:09,523 - util.py[DEBUG]: Running command ['ssh-keygen', '-t', 'rsa', '-N', '', '-f', '/etc/ssh/ssh_host_rsa_key'] with allowed return codes [0] (shell=False, capture=True)
2018-01-25 00:41:09,563 - util.py[DEBUG]: Running command ['ssh-keygen', '-t', 'dsa', '-N', '', '-f', '/etc/ssh/ssh_host_dsa_key'] with allowed return codes [0] (shell=False, capture=True)
2018-01-25 00:41:09,710 - util.py[DEBUG]: Running command ['ssh-keygen', '-t', 'ecdsa', '-N', '', '-f', '/etc/ssh/ssh_host_ecdsa_key'] with allowed return codes [0] (shell=False, capture=True)
2018-01-25 00:41:09,715 - util.py[DEBUG]: Running command ['ssh-keygen', '-t', 'ed25519', '-N', '', '-f', '/etc/ssh/ssh_host_ed25519_key'] with allowed return codes [0] (shell=False, capture=True)
2018-01-25 00:41:09,723 - util.py[DEBUG]: Changing the ownership of /root/.ssh to 0:0
2018-01-25 00:41:09,724 - util.py[DEBUG]: Reading from /etc/ssh/sshd_config (quiet=False)
2018-01-25 00:41:09,724 - util.py[DEBUG]: Read 2511 bytes from /etc/ssh/sshd_config
2018-01-25 00:41:09,725 - util.py[DEBUG]: Writing to /root/.ssh/authorized_keys - wb: [600] 404 bytes
2018-01-25 00:41:09,726 - util.py[DEBUG]: Changing the ownership of /root/.ssh/authorized_keys to 0:0
2018-01-25 00:41:09,727 - util.py[DEBUG]: Reading from /etc/ssh/sshd_config (quiet=False)
2018-01-25 00:41:09,727 - util.py[DEBUG]: Read 2511 bytes from /etc/ssh/sshd_config
2018-01-25 00:41:09,727 - util.py[DEBUG]: Reading from /root/.ssh/authorized_keys (quiet=False)
2018-01-25 00:41:09,727 - util.py[DEBUG]: Read 404 bytes from /root/.ssh/authorized_keys
2018-01-25 00:41:09,728 - util.py[DEBUG]: Writing to /root/.ssh/authorized_keys - wb: [600] 404 bytes
2018-01-25 00:41:09,729 - util.py[DEBUG]: Changing the ownership of /root/.ssh/authorized_keys to 0:0
2018-01-25 00:41:09,729 - handlers.py[DEBUG]: finish: init-network/config-ssh: SUCCESS: config-ssh ran successfully
2018-01-25 00:41:09,730 - main.py[DEBUG]: Ran 15 modules with 0 failures
2018-01-25 00:41:09,731 - util.py[DEBUG]: Reading from /proc/uptime (quiet=False)
2018-01-25 00:41:09,731 - util.py[DEBUG]: Read 11 bytes from /proc/uptime
2018-01-25 00:41:09,731 - util.py[DEBUG]: cloud-init mode 'init' took 0.652 seconds (0.65)
2018-01-25 00:41:09,731 - handlers.py[DEBUG]: finish: init-network: SUCCESS: searching for network datasources
2018-01-25 00:41:10,413 - util.py[DEBUG]: Cloud-init v. 17.1 running 'modules:config' at Thu, 25 Jan 2018 00:41:10 +0000. Up 8.56 seconds.
2018-01-25 00:41:10,457 - stages.py[DEBUG]: Using distro class <class 'cloudinit.distros.ubuntu.Distro'>
2018-01-25 00:41:10,458 - stages.py[DEBUG]: Running module emit_upstart (<module 'cloudinit.config.cc_emit_upstart' from '/usr/lib/python3/dist-packages/cloudinit/config/cc_emit_upstart.py'>) with frequency always
2018-01-25 00:41:10,459 - handlers.py[DEBUG]: start: modules-config/config-emit_upstart: running config-emit_upstart with frequency always
2018-01-25 00:41:10,459 - helpers.py[DEBUG]: Running config-emit_upstart using lock (<cloudinit.helpers.DummyLock object at 0x7f88aafad908>)
2018-01-25 00:41:10,459 - cc_emit_upstart.py[DEBUG]: no /sbin/initctl located
2018-01-25 00:41:10,459 - cc_emit_upstart.py[DEBUG]: not upstart system, 'emit_upstart' disabled
2018-01-25 00:41:10,459 - handlers.py[DEBUG]: finish: modules-config/config-emit_upstart: SUCCESS: config-emit_upstart ran successfully
2018-01-25 00:41:10,459 - stages.py[DEBUG]: Running module snap_config (<module 'cloudinit.config.cc_snap_config' from '/usr/lib/python3/dist-packages/cloudinit/config/cc_snap_config.py'>) with frequency once-per-instance
2018-01-25 00:41:10,460 - handlers.py[DEBUG]: start: modules-config/config-snap_config: running config-snap_config with frequency once-per-instance
2018-01-25 00:41:10,460 - util.py[DEBUG]: Writing to /var/lib/cloud/instances/80040526/sem/config_snap_config - wb: [644] 25 bytes
2018-01-25 00:41:10,460 - helpers.py[DEBUG]: Running config-snap_config using lock (<FileLock using file '/var/lib/cloud/instances/80040526/sem/config_snap_config'>)
2018-01-25 00:41:10,460 - cc_snap_config.py[DEBUG]: No snappy config provided, skipping
2018-01-25 00:41:10,460 - handlers.py[DEBUG]: finish: modules-config/config-snap_config: SUCCESS: config-snap_config ran successfully
2018-01-25 00:41:10,460 - stages.py[DEBUG]: Running module ssh-import-id (<module 'cloudinit.config.cc_ssh_import_id' from '/usr/lib/python3/dist-packages/cloudinit/config/cc_ssh_import_id.py'>) with frequency once-per-instance
2018-01-25 00:41:10,461 - handlers.py[DEBUG]: start: modules-config/config-ssh-import-id: running config-ssh-import-id with frequency once-per-instance
2018-01-25 00:41:10,461 - util.py[DEBUG]: Writing to /var/lib/cloud/instances/80040526/sem/config_ssh_import_id - wb: [644] 25 bytes
2018-01-25 00:41:10,461 - helpers.py[DEBUG]: Running config-ssh-import-id using lock (<FileLock using file '/var/lib/cloud/instances/80040526/sem/config_ssh_import_id'>)
2018-01-25 00:41:10,462 - handlers.py[DEBUG]: finish: modules-config/config-ssh-import-id: SUCCESS: config-ssh-import-id ran successfully
2018-01-25 00:41:10,462 - stages.py[DEBUG]: Running module locale (<module 'cloudinit.config.cc_locale' from '/usr/lib/python3/dist-packages/cloudinit/config/cc_locale.py'>) with frequency once-per-instance
2018-01-25 00:41:10,462 - handlers.py[DEBUG]: start: modules-config/config-locale: running config-locale with frequency once-per-instance
2018-01-25 00:41:10,462 - util.py[DEBUG]: Writing to /var/lib/cloud/instances/80040526/sem/config_locale - wb: [644] 25 bytes
2018-01-25 00:41:10,463 - helpers.py[DEBUG]: Running config-locale using lock (<FileLock using file '/var/lib/cloud/instances/80040526/sem/config_locale'>)
2018-01-25 00:41:10,463 - util.py[DEBUG]: Reading from /etc/default/locale (quiet=False)
2018-01-25 00:41:10,463 - util.py[DEBUG]: Read 35 bytes from /etc/default/locale
2018-01-25 00:41:10,463 - cc_locale.py[DEBUG]: Setting locale to en_US.UTF-8
2018-01-25 00:41:10,463 - util.py[DEBUG]: Reading from /etc/default/locale (quiet=False)
2018-01-25 00:41:10,463 - util.py[DEBUG]: Read 35 bytes from /etc/default/locale
2018-01-25 00:41:10,463 - debian.py[DEBUG]: Generating locales for en_US.UTF-8
2018-01-25 00:41:10,463 - util.py[DEBUG]: Running command ['locale-gen', 'en_US.UTF-8'] with allowed return codes [0] (shell=False, capture=False)
2018-01-25 00:41:11,721 - debian.py[DEBUG]: Updating /etc/default/locale with locale setting LANG=en_US.UTF-8
2018-01-25 00:41:11,721 - util.py[DEBUG]: Running command ['update-locale', '--locale-file=/etc/default/locale', 'LANG=en_US.UTF-8'] with allowed return codes [0] (shell=False, capture=False)
2018-01-25 00:41:11,745 - handlers.py[DEBUG]: finish: modules-config/config-locale: SUCCESS: config-locale ran successfully
2018-01-25 00:41:11,745 - stages.py[DEBUG]: Running module set-passwords (<module 'cloudinit.config.cc_set_passwords' from '/usr/lib/python3/dist-packages/cloudinit/config/cc_set_passwords.py'>) with frequency once-per-instance
2018-01-25 00:41:11,746 - handlers.py[DEBUG]: start: modules-config/config-set-passwords: running config-set-passwords with frequency once-per-instance
2018-01-25 00:41:11,746 - util.py[DEBUG]: Writing to /var/lib/cloud/instances/80040526/sem/config_set_passwords - wb: [644] 25 bytes
2018-01-25 00:41:11,747 - helpers.py[DEBUG]: Running config-set-passwords using lock (<FileLock using file '/var/lib/cloud/instances/80040526/sem/config_set_passwords'>)
2018-01-25 00:41:11,747 - util.py[DEBUG]: Reading from /etc/ssh/sshd_config (quiet=False)
2018-01-25 00:41:11,748 - util.py[DEBUG]: Read 2511 bytes from /etc/ssh/sshd_config
2018-01-25 00:41:11,748 - cc_set_passwords.py[DEBUG]: Replacing auth line 52 with no
2018-01-25 00:41:11,749 - util.py[DEBUG]: Writing to /etc/ssh/sshd_config - wb: [644] 2510 bytes
2018-01-25 00:41:11,749 - util.py[DEBUG]: Running command <filter object at 0x7f88aa803748> with allowed return codes [0] (shell=False, capture=True)
2018-01-25 00:41:11,789 - cc_set_passwords.py[DEBUG]: Restarted the ssh daemon
2018-01-25 00:41:11,790 - handlers.py[DEBUG]: finish: modules-config/config-set-passwords: SUCCESS: config-set-passwords ran successfully
2018-01-25 00:41:11,790 - stages.py[DEBUG]: Running module grub-dpkg (<module 'cloudinit.config.cc_grub_dpkg' from '/usr/lib/python3/dist-packages/cloudinit/config/cc_grub_dpkg.py'>) with frequency once-per-instance
2018-01-25 00:41:11,790 - handlers.py[DEBUG]: start: modules-config/config-grub-dpkg: running config-grub-dpkg with frequency once-per-instance
2018-01-25 00:41:11,791 - util.py[DEBUG]: Writing to /var/lib/cloud/instances/80040526/sem/config_grub_dpkg - wb: [644] 25 bytes
2018-01-25 00:41:11,791 - helpers.py[DEBUG]: Running config-grub-dpkg using lock (<FileLock using file '/var/lib/cloud/instances/80040526/sem/config_grub_dpkg'>)
2018-01-25 00:41:11,791 - cc_grub_dpkg.py[DEBUG]: Setting grub debconf-set-selections with '/dev/vda','false'
2018-01-25 00:41:11,791 - util.py[DEBUG]: Running command ['debconf-set-selections'] with allowed return codes [0] (shell=False, capture=True)
2018-01-25 00:41:11,933 - handlers.py[DEBUG]: finish: modules-config/config-grub-dpkg: SUCCESS: config-grub-dpkg ran successfully
2018-01-25 00:41:11,933 - stages.py[DEBUG]: Running module apt-pipelining (<module 'cloudinit.config.cc_apt_pipelining' from '/usr/lib/python3/dist-packages/cloudinit/config/cc_apt_pipelining.py'>) with frequency once-per-instance
2018-01-25 00:41:11,934 - handlers.py[DEBUG]: start: modules-config/config-apt-pipelining: running config-apt-pipelining with frequency once-per-instance
2018-01-25 00:41:11,934 - util.py[DEBUG]: Writing to /var/lib/cloud/instances/80040526/sem/config_apt_pipelining - wb: [644] 25 bytes
2018-01-25 00:41:11,935 - helpers.py[DEBUG]: Running config-apt-pipelining using lock (<FileLock using file '/var/lib/cloud/instances/80040526/sem/config_apt_pipelining'>)
2018-01-25 00:41:11,935 - util.py[DEBUG]: Writing to /etc/apt/apt.conf.d/90cloud-init-pipelining - wb: [644] 80 bytes
2018-01-25 00:41:11,936 - cc_apt_pipelining.py[DEBUG]: Wrote /etc/apt/apt.conf.d/90cloud-init-pipelining with apt pipeline depth setting 0
2018-01-25 00:41:11,936 - handlers.py[DEBUG]: finish: modules-config/config-apt-pipelining: SUCCESS: config-apt-pipelining ran successfully
2018-01-25 00:41:11,936 - stages.py[DEBUG]: Running module apt-configure (<module 'cloudinit.config.cc_apt_configure' from '/usr/lib/python3/dist-packages/cloudinit/config/cc_apt_configure.py'>) with frequency once-per-instance
2018-01-25 00:41:11,936 - handlers.py[DEBUG]: start: modules-config/config-apt-configure: running config-apt-configure with frequency once-per-instance
2018-01-25 00:41:11,937 - util.py[DEBUG]: Writing to /var/lib/cloud/instances/80040526/sem/config_apt_configure - wb: [644] 25 bytes
2018-01-25 00:41:11,937 - helpers.py[DEBUG]: Running config-apt-configure using lock (<FileLock using file '/var/lib/cloud/instances/80040526/sem/config_apt_configure'>)
2018-01-25 00:41:11,937 - cc_apt_configure.py[DEBUG]: debconf_selections was not set in config
2018-01-25 00:41:11,937 - util.py[DEBUG]: Reading from /etc/os-release (quiet=True)
2018-01-25 00:41:11,937 - util.py[DEBUG]: Read 298 bytes from /etc/os-release
2018-01-25 00:41:11,938 - util.py[DEBUG]: Reading from /etc/system-image/channel.ini (quiet=True)
2018-01-25 00:41:11,938 - util.py[DEBUG]: Read 0 bytes from /etc/system-image/channel.ini
2018-01-25 00:41:11,938 - cc_apt_configure.py[DEBUG]: handling apt config: {}
2018-01-25 00:41:11,938 - util.py[DEBUG]: Running command ['lsb_release', '--all'] with allowed return codes [0] (shell=False, capture=True)
2018-01-25 00:41:12,002 - util.py[DEBUG]: Running command ['dpkg', '--print-architecture'] with allowed return codes [0] (shell=False, capture=True)
2018-01-25 00:41:12,006 - cc_apt_configure.py[DEBUG]: got primary mirror: None
2018-01-25 00:41:12,007 - cc_apt_configure.py[DEBUG]: got security mirror: None
2018-01-25 00:41:12,007 - util.py[DEBUG]: Running command ['dpkg', '--print-architecture'] with allowed return codes [0] (shell=False, capture=True)
2018-01-25 00:41:12,015 - __init__.py[DEBUG]: filtered distro mirror info: {'security': 'http://security.ubuntu.com/ubuntu', 'primary': 'http://mirrors.digitalocean.com/ubuntu/'}
2018-01-25 00:41:12,015 - cc_apt_configure.py[DEBUG]: Apt Mirror info: {'PRIMARY': 'http://mirrors.digitalocean.com/ubuntu/', 'security': 'http://security.ubuntu.com/ubuntu', 'primary': 'http://mirrors.digitalocean.com/ubuntu/', 'MIRROR': 'http://mirrors.digitalocean.com/ubuntu/', 'SECURITY': 'http://security.ubuntu.com/ubuntu'}
2018-01-25 00:41:12,015 - cc_apt_configure.py[INFO]: No custom template provided, fall back to builtin
2018-01-25 00:41:12,016 - util.py[DEBUG]: Reading from /etc/cloud/templates/sources.list.ubuntu.tmpl (quiet=False)
2018-01-25 00:41:12,016 - util.py[DEBUG]: Read 2841 bytes from /etc/cloud/templates/sources.list.ubuntu.tmpl
2018-01-25 00:41:12,024 - util.py[DEBUG]: Writing to /etc/apt/sources.list - wb: [644] 3223 bytes
2018-01-25 00:41:12,025 - util.py[DEBUG]: Running command ['dpkg', '--print-architecture'] with allowed return codes [0] (shell=False, capture=True)
2018-01-25 00:41:12,029 - cc_apt_configure.py[DEBUG]: Renaming apt list /var/lib/apt/lists/archive.ubuntu.com_ubuntu_dists_xenial-updates_main_binary-amd64_Packages to /var/lib/apt/lists/mirrors.digitalocean.com_ubuntu_dists_xenial-updates_main_binary-amd64_Packages
2018-01-25 00:41:12,030 - cc_apt_configure.py[DEBUG]: Renaming apt list /var/lib/apt/lists/archive.ubuntu.com_ubuntu_dists_xenial-updates_restricted_binary-amd64_Packages to /var/lib/apt/lists/mirrors.digitalocean.com_ubuntu_dists_xenial-updates_restricted_binary-amd64_Packages
2018-01-25 00:41:12,030 - cc_apt_configure.py[DEBUG]: Renaming apt list /var/lib/apt/lists/archive.ubuntu.com_ubuntu_dists_xenial_restricted_binary-amd64_Packages to /var/lib/apt/lists/mirrors.digitalocean.com_ubuntu_dists_xenial_restricted_binary-amd64_Packages
2018-01-25 00:41:12,030 - cc_apt_configure.py[DEBUG]: Renaming apt list /var/lib/apt/lists/archive.ubuntu.com_ubuntu_dists_xenial_restricted_i18n_Translation-en to /var/lib/apt/lists/mirrors.digitalocean.com_ubuntu_dists_xenial_restricted_i18n_Translation-en
2018-01-25 00:41:12,030 - cc_apt_configure.py[DEBUG]: Renaming apt list /var/lib/apt/lists/archive.ubuntu.com_ubuntu_dists_xenial-updates_main_i18n_Translation-en to /var/lib/apt/lists/mirrors.digitalocean.com_ubuntu_dists_xenial-updates_main_i18n_Translation-en
2018-01-25 00:41:12,030 - cc_apt_configure.py[DEBUG]: Renaming apt list /var/lib/apt/lists/archive.ubuntu.com_ubuntu_dists_xenial-updates_InRelease to /var/lib/apt/lists/mirrors.digitalocean.com_ubuntu_dists_xenial-updates_InRelease
2018-01-25 00:41:12,030 - cc_apt_configure.py[DEBUG]: Renaming apt list /var/lib/apt/lists/archive.ubuntu.com_ubuntu_dists_xenial-updates_restricted_i18n_Translation-en to /var/lib/apt/lists/mirrors.digitalocean.com_ubuntu_dists_xenial-updates_restricted_i18n_Translation-en
2018-01-25 00:41:12,030 - cc_apt_configure.py[DEBUG]: Renaming apt list /var/lib/apt/lists/archive.ubuntu.com_ubuntu_dists_xenial_main_binary-amd64_Packages to /var/lib/apt/lists/mirrors.digitalocean.com_ubuntu_dists_xenial_main_binary-amd64_Packages
2018-01-25 00:41:12,030 - cc_apt_configure.py[DEBUG]: Renaming apt list /var/lib/apt/lists/archive.ubuntu.com_ubuntu_dists_xenial_main_i18n_Translation-en to /var/lib/apt/lists/mirrors.digitalocean.com_ubuntu_dists_xenial_main_i18n_Translation-en
2018-01-25 00:41:12,030 - cc_apt_configure.py[DEBUG]: Renaming apt list /var/lib/apt/lists/archive.ubuntu.com_ubuntu_dists_xenial_InRelease to /var/lib/apt/lists/mirrors.digitalocean.com_ubuntu_dists_xenial_InRelease
2018-01-25 00:41:12,031 - handlers.py[DEBUG]: finish: modules-config/config-apt-configure: SUCCESS: config-apt-configure ran successfully
2018-01-25 00:41:12,031 - stages.py[DEBUG]: Running module ntp (<module 'cloudinit.config.cc_ntp' from '/usr/lib/python3/dist-packages/cloudinit/config/cc_ntp.py'>) with frequency once-per-instance
2018-01-25 00:41:12,031 - handlers.py[DEBUG]: start: modules-config/config-ntp: running config-ntp with frequency once-per-instance
2018-01-25 00:41:12,031 - util.py[DEBUG]: Writing to /var/lib/cloud/instances/80040526/sem/config_ntp - wb: [644] 25 bytes
2018-01-25 00:41:12,032 - helpers.py[DEBUG]: Running config-ntp using lock (<FileLock using file '/var/lib/cloud/instances/80040526/sem/config_ntp'>)
2018-01-25 00:41:12,032 - cc_ntp.py[DEBUG]: Skipping module named ntp, not present or disabled by cfg
2018-01-25 00:41:12,032 - handlers.py[DEBUG]: finish: modules-config/config-ntp: SUCCESS: config-ntp ran successfully
2018-01-25 00:41:12,032 - stages.py[DEBUG]: Running module timezone (<module 'cloudinit.config.cc_timezone' from '/usr/lib/python3/dist-packages/cloudinit/config/cc_timezone.py'>) with frequency once-per-instance
2018-01-25 00:41:12,032 - handlers.py[DEBUG]: start: modules-config/config-timezone: running config-timezone with frequency once-per-instance
2018-01-25 00:41:12,033 - util.py[DEBUG]: Writing to /var/lib/cloud/instances/80040526/sem/config_timezone - wb: [644] 23 bytes
2018-01-25 00:41:12,033 - helpers.py[DEBUG]: Running config-timezone using lock (<FileLock using file '/var/lib/cloud/instances/80040526/sem/config_timezone'>)
2018-01-25 00:41:12,033 - cc_timezone.py[DEBUG]: Skipping module named timezone, no 'timezone' specified
2018-01-25 00:41:12,033 - handlers.py[DEBUG]: finish: modules-config/config-timezone: SUCCESS: config-timezone ran successfully
2018-01-25 00:41:12,033 - stages.py[DEBUG]: Running module disable-ec2-metadata (<module 'cloudinit.config.cc_disable_ec2_metadata' from '/usr/lib/python3/dist-packages/cloudinit/config/cc_disable_ec2_metadata.py'>) with frequency always
2018-01-25 00:41:12,033 - handlers.py[DEBUG]: start: modules-config/config-disable-ec2-metadata: running config-disable-ec2-metadata with frequency always
2018-01-25 00:41:12,034 - helpers.py[DEBUG]: Running config-disable-ec2-metadata using lock (<cloudinit.helpers.DummyLock object at 0x7f88aafa7940>)
2018-01-25 00:41:12,034 - cc_disable_ec2_metadata.py[DEBUG]: Skipping module named disable-ec2-metadata, disabling the ec2 route not enabled
2018-01-25 00:41:12,034 - handlers.py[DEBUG]: finish: modules-config/config-disable-ec2-metadata: SUCCESS: config-disable-ec2-metadata ran successfully
2018-01-25 00:41:12,034 - stages.py[DEBUG]: Running module runcmd (<module 'cloudinit.config.cc_runcmd' from '/usr/lib/python3/dist-packages/cloudinit/config/cc_runcmd.py'>) with frequency once-per-instance
2018-01-25 00:41:12,034 - handlers.py[DEBUG]: start: modules-config/config-runcmd: running config-runcmd with frequency once-per-instance
2018-01-25 00:41:12,034 - util.py[DEBUG]: Writing to /var/lib/cloud/instances/80040526/sem/config_runcmd - wb: [644] 25 bytes
2018-01-25 00:41:12,035 - helpers.py[DEBUG]: Running config-runcmd using lock (<FileLock using file '/var/lib/cloud/instances/80040526/sem/config_runcmd'>)
2018-01-25 00:41:12,035 - cc_runcmd.py[DEBUG]: Skipping module named runcmd, no 'runcmd' key in configuration
2018-01-25 00:41:12,035 - handlers.py[DEBUG]: finish: modules-config/config-runcmd: SUCCESS: config-runcmd ran successfully
2018-01-25 00:41:12,035 - stages.py[DEBUG]: Running module byobu (<module 'cloudinit.config.cc_byobu' from '/usr/lib/python3/dist-packages/cloudinit/config/cc_byobu.py'>) with frequency once-per-instance
2018-01-25 00:41:12,035 - handlers.py[DEBUG]: start: modules-config/config-byobu: running config-byobu with frequency once-per-instance
2018-01-25 00:41:12,035 - util.py[DEBUG]: Writing to /var/lib/cloud/instances/80040526/sem/config_byobu - wb: [644] 25 bytes
2018-01-25 00:41:12,036 - helpers.py[DEBUG]: Running config-byobu using lock (<FileLock using file '/var/lib/cloud/instances/80040526/sem/config_byobu'>)
2018-01-25 00:41:12,036 - cc_byobu.py[DEBUG]: Skipping module named byobu, no 'byobu' values found
2018-01-25 00:41:12,036 - handlers.py[DEBUG]: finish: modules-config/config-byobu: SUCCESS: config-byobu ran successfully
2018-01-25 00:41:12,036 - main.py[DEBUG]: Ran 13 modules with 0 failures
2018-01-25 00:41:12,037 - util.py[DEBUG]: Reading from /proc/uptime (quiet=False)
2018-01-25 00:41:12,037 - util.py[DEBUG]: Read 12 bytes from /proc/uptime
2018-01-25 00:41:12,037 - util.py[DEBUG]: cloud-init mode 'modules' took 1.865 seconds (1.86)
2018-01-25 00:41:12,037 - handlers.py[DEBUG]: finish: modules-config: SUCCESS: running modules for config
2018-01-25 00:41:12,458 - util.py[DEBUG]: Cloud-init v. 17.1 running 'modules:final' at Thu, 25 Jan 2018 00:41:12 +0000. Up 10.63 seconds.
2018-01-25 00:41:12,503 - stages.py[DEBUG]: Using distro class <class 'cloudinit.distros.ubuntu.Distro'>
2018-01-25 00:41:12,504 - stages.py[DEBUG]: Running module snappy (<module 'cloudinit.config.cc_snappy' from '/usr/lib/python3/dist-packages/cloudinit/config/cc_snappy.py'>) with frequency once-per-instance
2018-01-25 00:41:12,504 - handlers.py[DEBUG]: start: modules-final/config-snappy: running config-snappy with frequency once-per-instance
2018-01-25 00:41:12,505 - util.py[DEBUG]: Writing to /var/lib/cloud/instances/80040526/sem/config_snappy - wb: [644] 24 bytes
2018-01-25 00:41:12,505 - helpers.py[DEBUG]: Running config-snappy using lock (<FileLock using file '/var/lib/cloud/instances/80040526/sem/config_snappy'>)
2018-01-25 00:41:12,505 - util.py[DEBUG]: Reading from /etc/os-release (quiet=True)
2018-01-25 00:41:12,506 - util.py[DEBUG]: Read 298 bytes from /etc/os-release
2018-01-25 00:41:12,506 - util.py[DEBUG]: Reading from /etc/system-image/channel.ini (quiet=True)
2018-01-25 00:41:12,506 - util.py[DEBUG]: Read 0 bytes from /etc/system-image/channel.ini
2018-01-25 00:41:12,506 - cc_snappy.py[DEBUG]: snappy: 'auto' mode, and system not snappy
2018-01-25 00:41:12,507 - handlers.py[DEBUG]: finish: modules-final/config-snappy: SUCCESS: config-snappy ran successfully
2018-01-25 00:41:12,507 - stages.py[DEBUG]: Running module package-update-upgrade-install (<module 'cloudinit.config.cc_package_update_upgrade_install' from '/usr/lib/python3/dist-packages/cloudinit/config/cc_package_update_upgrade_install.py'>) with frequency once-per-instance
2018-01-25 00:41:12,508 - handlers.py[DEBUG]: start: modules-final/config-package-update-upgrade-install: running config-package-update-upgrade-install with frequency once-per-instance
2018-01-25 00:41:12,508 - util.py[DEBUG]: Writing to /var/lib/cloud/instances/80040526/sem/config_package_update_upgrade_install - wb: [644] 25 bytes
2018-01-25 00:41:12,508 - helpers.py[DEBUG]: Running config-package-update-upgrade-install using lock (<FileLock using file '/var/lib/cloud/instances/80040526/sem/config_package_update_upgrade_install'>)
2018-01-25 00:41:12,508 - handlers.py[DEBUG]: finish: modules-final/config-package-update-upgrade-install: SUCCESS: config-package-update-upgrade-install ran successfully
2018-01-25 00:41:12,508 - stages.py[DEBUG]: Running module fan (<module 'cloudinit.config.cc_fan' from '/usr/lib/python3/dist-packages/cloudinit/config/cc_fan.py'>) with frequency once-per-instance
2018-01-25 00:41:12,509 - handlers.py[DEBUG]: start: modules-final/config-fan: running config-fan with frequency once-per-instance
2018-01-25 00:41:12,509 - util.py[DEBUG]: Writing to /var/lib/cloud/instances/80040526/sem/config_fan - wb: [644] 25 bytes
2018-01-25 00:41:12,509 - helpers.py[DEBUG]: Running config-fan using lock (<FileLock using file '/var/lib/cloud/instances/80040526/sem/config_fan'>)
2018-01-25 00:41:12,509 - cc_fan.py[DEBUG]: fan: no 'fan' config entry. disabling
2018-01-25 00:41:12,510 - handlers.py[DEBUG]: finish: modules-final/config-fan: SUCCESS: config-fan ran successfully
2018-01-25 00:41:12,510 - stages.py[DEBUG]: Running module landscape (<module 'cloudinit.config.cc_landscape' from '/usr/lib/python3/dist-packages/cloudinit/config/cc_landscape.py'>) with frequency once-per-instance
2018-01-25 00:41:12,510 - handlers.py[DEBUG]: start: modules-final/config-landscape: running config-landscape with frequency once-per-instance
2018-01-25 00:41:12,510 - util.py[DEBUG]: Writing to /var/lib/cloud/instances/80040526/sem/config_landscape - wb: [644] 24 bytes
2018-01-25 00:41:12,511 - helpers.py[DEBUG]: Running config-landscape using lock (<FileLock using file '/var/lib/cloud/instances/80040526/sem/config_landscape'>)
2018-01-25 00:41:12,511 - handlers.py[DEBUG]: finish: modules-final/config-landscape: SUCCESS: config-landscape ran successfully
2018-01-25 00:41:12,511 - stages.py[DEBUG]: Running module lxd (<module 'cloudinit.config.cc_lxd' from '/usr/lib/python3/dist-packages/cloudinit/config/cc_lxd.py'>) with frequency once-per-instance
2018-01-25 00:41:12,511 - handlers.py[DEBUG]: start: modules-final/config-lxd: running config-lxd with frequency once-per-instance
2018-01-25 00:41:12,511 - util.py[DEBUG]: Writing to /var/lib/cloud/instances/80040526/sem/config_lxd - wb: [644] 24 bytes
2018-01-25 00:41:12,512 - helpers.py[DEBUG]: Running config-lxd using lock (<FileLock using file '/var/lib/cloud/instances/80040526/sem/config_lxd'>)
2018-01-25 00:41:12,512 - cc_lxd.py[DEBUG]: Skipping module named lxd, not present or disabled by cfg
2018-01-25 00:41:12,512 - handlers.py[DEBUG]: finish: modules-final/config-lxd: SUCCESS: config-lxd ran successfully
2018-01-25 00:41:12,512 - stages.py[DEBUG]: Running module puppet (<module 'cloudinit.config.cc_puppet' from '/usr/lib/python3/dist-packages/cloudinit/config/cc_puppet.py'>) with frequency once-per-instance
2018-01-25 00:41:12,512 - handlers.py[DEBUG]: start: modules-final/config-puppet: running config-puppet with frequency once-per-instance
2018-01-25 00:41:12,512 - util.py[DEBUG]: Writing to /var/lib/cloud/instances/80040526/sem/config_puppet - wb: [644] 25 bytes
2018-01-25 00:41:12,513 - helpers.py[DEBUG]: Running config-puppet using lock (<FileLock using file '/var/lib/cloud/instances/80040526/sem/config_puppet'>)
2018-01-25 00:41:12,513 - cc_puppet.py[DEBUG]: Skipping module named puppet, no 'puppet' configuration found
2018-01-25 00:41:12,513 - handlers.py[DEBUG]: finish: modules-final/config-puppet: SUCCESS: config-puppet ran successfully
2018-01-25 00:41:12,513 - stages.py[DEBUG]: Running module chef (<module 'cloudinit.config.cc_chef' from '/usr/lib/python3/dist-packages/cloudinit/config/cc_chef.py'>) with frequency once-per-instance
2018-01-25 00:41:12,513 - handlers.py[DEBUG]: start: modules-final/config-chef: running config-chef with frequency once-per-instance
2018-01-25 00:41:12,513 - util.py[DEBUG]: Writing to /var/lib/cloud/instances/80040526/sem/config_chef - wb: [644] 25 bytes
2018-01-25 00:41:12,514 - helpers.py[DEBUG]: Running config-chef using lock (<FileLock using file '/var/lib/cloud/instances/80040526/sem/config_chef'>)
2018-01-25 00:41:12,514 - cc_chef.py[DEBUG]: Skipping module named chef, no 'chef' key in configuration
2018-01-25 00:41:12,514 - handlers.py[DEBUG]: finish: modules-final/config-chef: SUCCESS: config-chef ran successfully
2018-01-25 00:41:12,514 - stages.py[DEBUG]: Running module salt-minion (<module 'cloudinit.config.cc_salt_minion' from '/usr/lib/python3/dist-packages/cloudinit/config/cc_salt_minion.py'>) with frequency once-per-instance
2018-01-25 00:41:12,514 - handlers.py[DEBUG]: start: modules-final/config-salt-minion: running config-salt-minion with frequency once-per-instance
2018-01-25 00:41:12,514 - util.py[DEBUG]: Writing to /var/lib/cloud/instances/80040526/sem/config_salt_minion - wb: [644] 24 bytes
2018-01-25 00:41:12,515 - helpers.py[DEBUG]: Running config-salt-minion using lock (<FileLock using file '/var/lib/cloud/instances/80040526/sem/config_salt_minion'>)
2018-01-25 00:41:12,515 - cc_salt_minion.py[DEBUG]: Skipping module named salt-minion, no 'salt_minion' key in configuration
2018-01-25 00:41:12,515 - handlers.py[DEBUG]: finish: modules-final/config-salt-minion: SUCCESS: config-salt-minion ran successfully
2018-01-25 00:41:12,515 - stages.py[DEBUG]: Running module mcollective (<module 'cloudinit.config.cc_mcollective' from '/usr/lib/python3/dist-packages/cloudinit/config/cc_mcollective.py'>) with frequency once-per-instance
2018-01-25 00:41:12,515 - handlers.py[DEBUG]: start: modules-final/config-mcollective: running config-mcollective with frequency once-per-instance
2018-01-25 00:41:12,515 - util.py[DEBUG]: Writing to /var/lib/cloud/instances/80040526/sem/config_mcollective - wb: [644] 25 bytes
2018-01-25 00:41:12,516 - helpers.py[DEBUG]: Running config-mcollective using lock (<FileLock using file '/var/lib/cloud/instances/80040526/sem/config_mcollective'>)
2018-01-25 00:41:12,516 - cc_mcollective.py[DEBUG]: Skipping module named mcollective, no 'mcollective' key in configuration
2018-01-25 00:41:12,516 - handlers.py[DEBUG]: finish: modules-final/config-mcollective: SUCCESS: config-mcollective ran successfully
2018-01-25 00:41:12,516 - stages.py[DEBUG]: Running module rightscale_userdata (<module 'cloudinit.config.cc_rightscale_userdata' from '/usr/lib/python3/dist-packages/cloudinit/config/cc_rightscale_userdata.py'>) with frequency once-per-instance
2018-01-25 00:41:12,516 - handlers.py[DEBUG]: start: modules-final/config-rightscale_userdata: running config-rightscale_userdata with frequency once-per-instance
2018-01-25 00:41:12,517 - util.py[DEBUG]: Writing to /var/lib/cloud/instances/80040526/sem/config_rightscale_userdata - wb: [644] 25 bytes
2018-01-25 00:41:12,517 - helpers.py[DEBUG]: Running config-rightscale_userdata using lock (<FileLock using file '/var/lib/cloud/instances/80040526/sem/config_rightscale_userdata'>)
2018-01-25 00:41:12,517 - cc_rightscale_userdata.py[DEBUG]: Failed to get raw userdata in module rightscale_userdata
2018-01-25 00:41:12,517 - handlers.py[DEBUG]: finish: modules-final/config-rightscale_userdata: SUCCESS: config-rightscale_userdata ran successfully
2018-01-25 00:41:12,517 - stages.py[DEBUG]: Running module scripts-vendor (<module 'cloudinit.config.cc_scripts_vendor' from '/usr/lib/python3/dist-packages/cloudinit/config/cc_scripts_vendor.py'>) with frequency once-per-instance
2018-01-25 00:41:12,518 - handlers.py[DEBUG]: start: modules-final/config-scripts-vendor: running config-scripts-vendor with frequency once-per-instance
2018-01-25 00:41:12,518 - util.py[DEBUG]: Writing to /var/lib/cloud/instances/80040526/sem/config_scripts_vendor - wb: [644] 25 bytes
2018-01-25 00:41:12,518 - helpers.py[DEBUG]: Running config-scripts-vendor using lock (<FileLock using file '/var/lib/cloud/instances/80040526/sem/config_scripts_vendor'>)
2018-01-25 00:41:12,518 - handlers.py[DEBUG]: finish: modules-final/config-scripts-vendor: SUCCESS: config-scripts-vendor ran successfully
2018-01-25 00:41:12,518 - stages.py[DEBUG]: Running module scripts-per-once (<module 'cloudinit.config.cc_scripts_per_once' from '/usr/lib/python3/dist-packages/cloudinit/config/cc_scripts_per_once.py'>) with frequency once
2018-01-25 00:41:12,519 - handlers.py[DEBUG]: start: modules-final/config-scripts-per-once: running config-scripts-per-once with frequency once
2018-01-25 00:41:12,519 - util.py[DEBUG]: Writing to /var/lib/cloud/sem/config_scripts_per_once.once - wb: [644] 25 bytes
2018-01-25 00:41:12,519 - helpers.py[DEBUG]: Running config-scripts-per-once using lock (<FileLock using file '/var/lib/cloud/sem/config_scripts_per_once.once'>)
2018-01-25 00:41:12,519 - handlers.py[DEBUG]: finish: modules-final/config-scripts-per-once: SUCCESS: config-scripts-per-once ran successfully
2018-01-25 00:41:12,519 - stages.py[DEBUG]: Running module scripts-per-boot (<module 'cloudinit.config.cc_scripts_per_boot' from '/usr/lib/python3/dist-packages/cloudinit/config/cc_scripts_per_boot.py'>) with frequency always
2018-01-25 00:41:12,520 - handlers.py[DEBUG]: start: modules-final/config-scripts-per-boot: running config-scripts-per-boot with frequency always
2018-01-25 00:41:12,520 - helpers.py[DEBUG]: Running config-scripts-per-boot using lock (<cloudinit.helpers.DummyLock object at 0x7f7f61b895f8>)
2018-01-25 00:41:12,520 - handlers.py[DEBUG]: finish: modules-final/config-scripts-per-boot: SUCCESS: config-scripts-per-boot ran successfully
2018-01-25 00:41:12,520 - stages.py[DEBUG]: Running module scripts-per-instance (<module 'cloudinit.config.cc_scripts_per_instance' from '/usr/lib/python3/dist-packages/cloudinit/config/cc_scripts_per_instance.py'>) with frequency once-per-instance
2018-01-25 00:41:12,520 - handlers.py[DEBUG]: start: modules-final/config-scripts-per-instance: running config-scripts-per-instance with frequency once-per-instance
2018-01-25 00:41:12,520 - util.py[DEBUG]: Writing to /var/lib/cloud/instances/80040526/sem/config_scripts_per_instance - wb: [644] 24 bytes
2018-01-25 00:41:12,521 - helpers.py[DEBUG]: Running config-scripts-per-instance using lock (<FileLock using file '/var/lib/cloud/instances/80040526/sem/config_scripts_per_instance'>)
2018-01-25 00:41:12,521 - util.py[DEBUG]: Running command ['/var/lib/cloud/scripts/per-instance/machine_id.sh'] with allowed return codes [0] (shell=False, capture=False)
2018-01-25 00:41:12,526 - handlers.py[DEBUG]: finish: modules-final/config-scripts-per-instance: SUCCESS: config-scripts-per-instance ran successfully
2018-01-25 00:41:12,527 - stages.py[DEBUG]: Running module scripts-user (<module 'cloudinit.config.cc_scripts_user' from '/usr/lib/python3/dist-packages/cloudinit/config/cc_scripts_user.py'>) with frequency once-per-instance
2018-01-25 00:41:12,527 - handlers.py[DEBUG]: start: modules-final/config-scripts-user: running config-scripts-user with frequency once-per-instance
2018-01-25 00:41:12,527 - util.py[DEBUG]: Writing to /var/lib/cloud/instances/80040526/sem/config_scripts_user - wb: [644] 25 bytes
2018-01-25 00:41:12,528 - helpers.py[DEBUG]: Running config-scripts-user using lock (<FileLock using file '/var/lib/cloud/instances/80040526/sem/config_scripts_user'>)
2018-01-25 00:41:12,528 - handlers.py[DEBUG]: finish: modules-final/config-scripts-user: SUCCESS: config-scripts-user ran successfully
2018-01-25 00:41:12,528 - stages.py[DEBUG]: Running module ssh-authkey-fingerprints (<module 'cloudinit.config.cc_ssh_authkey_fingerprints' from '/usr/lib/python3/dist-packages/cloudinit/config/cc_ssh_authkey_fingerprints.py'>) with frequency once-per-instance
2018-01-25 00:41:12,528 - handlers.py[DEBUG]: start: modules-final/config-ssh-authkey-fingerprints: running config-ssh-authkey-fingerprints with frequency once-per-instance
2018-01-25 00:41:12,529 - util.py[DEBUG]: Writing to /var/lib/cloud/instances/80040526/sem/config_ssh_authkey_fingerprints - wb: [644] 25 bytes
2018-01-25 00:41:12,529 - helpers.py[DEBUG]: Running config-ssh-authkey-fingerprints using lock (<FileLock using file '/var/lib/cloud/instances/80040526/sem/config_ssh_authkey_fingerprints'>)
2018-01-25 00:41:12,530 - util.py[DEBUG]: Reading from /etc/ssh/sshd_config (quiet=False)
2018-01-25 00:41:12,530 - util.py[DEBUG]: Read 2510 bytes from /etc/ssh/sshd_config
2018-01-25 00:41:12,530 - util.py[DEBUG]: Reading from /root/.ssh/authorized_keys (quiet=False)
2018-01-25 00:41:12,530 - util.py[DEBUG]: Read 404 bytes from /root/.ssh/authorized_keys
2018-01-25 00:41:12,537 - handlers.py[DEBUG]: finish: modules-final/config-ssh-authkey-fingerprints: SUCCESS: config-ssh-authkey-fingerprints ran successfully
2018-01-25 00:41:12,537 - stages.py[DEBUG]: Running module keys-to-console (<module 'cloudinit.config.cc_keys_to_console' from '/usr/lib/python3/dist-packages/cloudinit/config/cc_keys_to_console.py'>) with frequency once-per-instance
2018-01-25 00:41:12,538 - handlers.py[DEBUG]: start: modules-final/config-keys-to-console: running config-keys-to-console with frequency once-per-instance
2018-01-25 00:41:12,538 - util.py[DEBUG]: Writing to /var/lib/cloud/instances/80040526/sem/config_keys_to_console - wb: [644] 25 bytes
2018-01-25 00:41:12,538 - helpers.py[DEBUG]: Running config-keys-to-console using lock (<FileLock using file '/var/lib/cloud/instances/80040526/sem/config_keys_to_console'>)
2018-01-25 00:41:12,539 - util.py[DEBUG]: Running command ['/usr/lib/cloud-init/write-ssh-key-fingerprints', '', 'ssh-dss'] with allowed return codes [0] (shell=False, capture=True)
2018-01-25 00:41:12,563 - handlers.py[DEBUG]: finish: modules-final/config-keys-to-console: SUCCESS: config-keys-to-console ran successfully
2018-01-25 00:41:12,564 - stages.py[DEBUG]: Running module phone-home (<module 'cloudinit.config.cc_phone_home' from '/usr/lib/python3/dist-packages/cloudinit/config/cc_phone_home.py'>) with frequency once-per-instance
2018-01-25 00:41:12,564 - handlers.py[DEBUG]: start: modules-final/config-phone-home: running config-phone-home with frequency once-per-instance
2018-01-25 00:41:12,564 - util.py[DEBUG]: Writing to /var/lib/cloud/instances/80040526/sem/config_phone_home - wb: [644] 25 bytes
2018-01-25 00:41:12,565 - helpers.py[DEBUG]: Running config-phone-home using lock (<FileLock using file '/var/lib/cloud/instances/80040526/sem/config_phone_home'>)
2018-01-25 00:41:12,565 - cc_phone_home.py[DEBUG]: Skipping module named phone-home, no 'phone_home' configuration found
2018-01-25 00:41:12,565 - handlers.py[DEBUG]: finish: modules-final/config-phone-home: SUCCESS: config-phone-home ran successfully
2018-01-25 00:41:12,565 - stages.py[DEBUG]: Running module final-message (<module 'cloudinit.config.cc_final_message' from '/usr/lib/python3/dist-packages/cloudinit/config/cc_final_message.py'>) with frequency always
2018-01-25 00:41:12,566 - handlers.py[DEBUG]: start: modules-final/config-final-message: running config-final-message with frequency always
2018-01-25 00:41:12,566 - helpers.py[DEBUG]: Running config-final-message using lock (<cloudinit.helpers.DummyLock object at 0x7f7f613e6d30>)
2018-01-25 00:41:12,566 - util.py[DEBUG]: Reading from /proc/uptime (quiet=False)
2018-01-25 00:41:12,566 - util.py[DEBUG]: Read 12 bytes from /proc/uptime
2018-01-25 00:41:12,570 - util.py[DEBUG]: Cloud-init v. 17.1 finished at Thu, 25 Jan 2018 00:41:12 +0000. Datasource DataSourceDigitalOcean.  Up 10.84 seconds
2018-01-25 00:41:12,570 - util.py[DEBUG]: Writing to /var/lib/cloud/instance/boot-finished - wb: [644] 50 bytes
2018-01-25 00:41:12,570 - handlers.py[DEBUG]: finish: modules-final/config-final-message: SUCCESS: config-final-message ran successfully
2018-01-25 00:41:12,571 - stages.py[DEBUG]: Running module power-state-change (<module 'cloudinit.config.cc_power_state_change' from '/usr/lib/python3/dist-packages/cloudinit/config/cc_power_state_change.py'>) with frequency once-per-instance
2018-01-25 00:41:12,571 - handlers.py[DEBUG]: start: modules-final/config-power-state-change: running config-power-state-change with frequency once-per-instance
2018-01-25 00:41:12,571 - util.py[DEBUG]: Writing to /var/lib/cloud/instances/80040526/sem/config_power_state_change - wb: [644] 25 bytes
2018-01-25 00:41:12,571 - helpers.py[DEBUG]: Running config-power-state-change using lock (<FileLock using file '/var/lib/cloud/instances/80040526/sem/config_power_state_change'>)
2018-01-25 00:41:12,572 - cc_power_state_change.py[DEBUG]: no power_state provided. doing nothing
2018-01-25 00:41:12,572 - handlers.py[DEBUG]: finish: modules-final/config-power-state-change: SUCCESS: config-power-state-change ran successfully
2018-01-25 00:41:12,572 - main.py[DEBUG]: Ran 20 modules with 0 failures
2018-01-25 00:41:12,573 - util.py[DEBUG]: Creating symbolic link from '/run/cloud-init/result.json' => '../../var/lib/cloud/data/result.json'
2018-01-25 00:41:12,573 - util.py[DEBUG]: Reading from /proc/uptime (quiet=False)
2018-01-25 00:41:12,573 - util.py[DEBUG]: Read 12 bytes from /proc/uptime
2018-01-25 00:41:12,573 - util.py[DEBUG]: cloud-init mode 'modules' took 0.218 seconds (0.22)
2018-01-25 00:41:12,573 - handlers.py[DEBUG]: finish: modules-final: SUCCESS: running modules for final
